Workbook

Sheet Datos Preescolar
B1: Mes | C1: Día | D1: Estudiante | E1: Grado | F1: Como conoció el colegio | G1: Inicio proceso | H1: Observación | I1: Matrícula | J1: Estado del proceso | K1: Observaciones | L1: Días entre cita de info e inicio de observa | M1: Días entre inici de observa y matrícula | N1: Días entre cita de info y matrícula | O1: =AVERAGEIF(L2:L899,">0",L2:L899) -> 161.26087 | P1: =AVERAGEIF(M2:M899,">0",M2:M899) -> 42.611111 | Q1: =AVERAGEIF(N2:N899,">0",N2:N899) -> 195.16667 | S1: =AVERAGEIF(N2:N899,">0",L2:L899) -> 152.55556 | T1: =AVERAGEIF(N2:N899,">0",M2:M899) -> 42.611111
B2: Enero | C2: 44939 | D2: Alicia Barrientos | E2: Transición | G2: SI | H2: 44949 | I2: 44972 | L2: =IF(H2>0,H2-C2,0) -> 10 | M2: =IF(I2>0,I2-H2,0) -> 23 | N2: =IF(I2>0,I2-C2,0) -> 33
B3: Enero | C3: 44944 | D3: Antonia Tabares | E3: Prejardín | G3: NO | L3: =IF(H3>0,H3-C3,0) -> 0 | M3: =IF(I3>0,I3-H3,0) -> 0 | N3: =IF(I3>0,I3-C3,0) -> 0
B4: Enero | C4: 44944 | D4: Luna Waton Lu Jaramillo | E4: Prejardín | G4: NO | L4: =IF(H4>0,H4-C4,0) -> 0 | M4: =IF(I4>0,I4-H4,0) -> 0 | N4: =IF(I4>0,I4-C4,0) -> 0
B5: Enero | C5: 44944 | D5: Gabriela Díaz Arrieta | E5: Prejardín | G5: SI | H5: 45216 | I5: 45306 | L5: =IF(H5>0,H5-C5,0) -> 272 | M5: =IF(I5>0,I5-H5,0) -> 90 | N5: =IF(I5>0,I5-C5,0) -> 362
B6: Enero | C6: 44944 | D6: Elisa Delgado González | E6: Prejardín | G6: NO | L6: =IF(H6>0,H6-C6,0) -> 0 | M6: =IF(I6>0,I6-H6,0) -> 0 | N6: =IF(I6>0,I6-C6,0) -> 0
B7: Enero | C7: 44953 | D7: David Gabriel Peña Díaz | E7: Prejardín | G7: NO | L7: =IF(H7>0,H7-C7,0) -> 0 | M7: =IF(I7>0,I7-H7,0) -> 0 | N7: =IF(I7>0,I7-C7,0) -> 0
B8: Febrero | C8: 44958 | D8: Martina Páez Cano | E8: Prejardín | G8: NO | J8: Tenía cupo reservado y desitió | L8: =IF(H8>0,H8-C8,0) -> 0 | M8: =IF(I8>0,I8-H8,0) -> 0 | N8: =IF(I8>0,I8-C8,0) -> 0
B9: Febrero | C9: 44958 | D9: Lucio Arango Parra | E9: Prejardín | G9: NO | L9: =IF(H9>0,H9-C9,0) -> 0 | M9: =IF(I9>0,I9-H9,0) -> 0 | N9: =IF(I9>0,I9-C9,0) -> 0
B10: Febrero | C10: 44958 | D10: Amelia Gaitán | E10: Prejardín | G10: NO | L10: =IF(H10>0,H10-C10,0) -> 0 | M10: =IF(I10>0,I10-H10,0) -> 0 | N10: =IF(I10>0,I10-C10,0) -> 0
B11: Febrero | C11: 44968 | D11: Alicia Vasco García | E11: Transición | G11: SI | H11: 45222 | I11: 45306 | L11: =IF(H11>0,H11-C11,0) -> 254 | M11: =IF(I11>0,I11-H11,0) -> 84 | N11: =IF(I11>0,I11-C11,0) -> 338
B12: Febrero | C12: 44972 | D12: Guadalupe Pérez puerta | E12: Prejardín | G12: NO | L12: =IF(H12>0,H12-C12,0) -> 0 | M12: =IF(I12>0,I12-H12,0) -> 0 | N12: =IF(I12>0,I12-C12,0) -> 0
B13: Febrero | C13: 44972 | D13: Martín velasquez | E13: Jardín | G13: NO | L13: =IF(H13>0,H13-C13,0) -> 0 | M13: =IF(I13>0,I13-H13,0) -> 0 | N13: =IF(I13>0,I13-C13,0) -> 0
B14: Febrero | C14: 44972 | D14: Mayu Kiriki Ríos - Yudai Kiriki Ríos | E14: Transición | G14: NO | L14: =IF(H14>0,H14-C14,0) -> 0 | M14: =IF(I14>0,I14-H14,0) -> 0 | N14: =IF(I14>0,I14-C14,0) -> 0
B15: Marzo | C15: 45014 | D15: Agustín Hoyos Cruz | E15: Transición | G15: NO | L15: =IF(H15>0,H15-C15,0) -> 0 | M15: =IF(I15>0,I15-H15,0) -> 0 | N15: =IF(I15>0,I15-C15,0) -> 0
B16: Marzo | C16: 45014 | D16: Miguel Ángel Páez Montoya | E16: Transición | G16: NO | L16: =IF(H16>0,H16-C16,0) -> 0 | M16: =IF(I16>0,I16-H16,0) -> 0 | N16: =IF(I16>0,I16-C16,0) -> 0
B17: Marzo | C17: 45014 | D17: Juan Matías Fonseca | E17: Transición | G17: NO | L17: =IF(H17>0,H17-C17,0) -> 0 | M17: =IF(I17>0,I17-H17,0) -> 0 | N17: =IF(I17>0,I17-C17,0) -> 0
B18: Abril | C18: 45035 | D18: Matías Usma | E18: Jardín | G18: NO | L18: =IF(H18>0,H18-C18,0) -> 0 | M18: =IF(I18>0,I18-H18,0) -> 0 | N18: =IF(I18>0,I18-C18,0) -> 0
B19: Abril | C19: 45042 | D19: Luca Aristizábal Forero | E19: Prejardín | G19: NO | L19: =IF(H19>0,H19-C19,0) -> 0 | M19: =IF(I19>0,I19-H19,0) -> 0 | N19: =IF(I19>0,I19-C19,0) -> 0
B20: Abril | C20: 45042 | D20: Luiyi Fontalvo Gutiérrez | E20: Prejardín | G20: NO | L20: =IF(H20>0,H20-C20,0) -> 0 | M20: =IF(I20>0,I20-H20,0) -> 0 | N20: =IF(I20>0,I20-C20,0) -> 0
B21: Abril | C21: 45042 | D21: José Manuel Guzmán Barrera | E21: Prejardín | G21: NO | J21: Tenía cupo reservado y desitió | L21: =IF(H21>0,H21-C21,0) -> 0 | M21: =IF(I21>0,I21-H21,0) -> 0 | N21: =IF(I21>0,I21-C21,0) -> 0
B22: Abril | C22: 45043 | D22: Emilia Ocampo López | E22: Prejardín | G22: SI | H22: 45117 | I22: 45138 | L22: =IF(H22>0,H22-C22,0) -> 74 | M22: =IF(I22>0,I22-H22,0) -> 21 | N22: =IF(I22>0,I22-C22,0) -> 95
B23: Abril | C23: 45043 | D23: Aya Amor Correa Ramírez | E23: Prejardín | G23: NO | L23: =IF(H23>0,H23-C23,0) -> 0 | M23: =IF(I23>0,I23-H23,0) -> 0 | N23: =IF(I23>0,I23-C23,0) -> 0
B24: Abril | C24: 45043 | D24: Lucía Urbina Wilches | E24: Prejardín | G24: NO | L24: =IF(H24>0,H24-C24,0) -> 0 | M24: =IF(I24>0,I24-H24,0) -> 0 | N24: =IF(I24>0,I24-C24,0) -> 0
B25: Abril | C25: 45043 | D25: Pablo Jiménez Barrera | E25: Jardín | G25: NO | L25: =IF(H25>0,H25-C25,0) -> 0 | M25: =IF(I25>0,I25-H25,0) -> 0 | N25: =IF(I25>0,I25-C25,0) -> 0
B26: Mayo | C26: 45056 | D26: Agustín Diosa Bedoya | E26: Prejardín | G26: NO | L26: =IF(H26>0,H26-C26,0) -> 0 | M26: =IF(I26>0,I26-H26,0) -> 0 | N26: =IF(I26>0,I26-C26,0) -> 0
B27: Mayo | C27: 45056 | D27: Valentino Iguarán | E27: Jardín | G27: SI | H27: 45124 | I27: 45149 | L27: =IF(H27>0,H27-C27,0) -> 68 | M27: =IF(I27>0,I27-H27,0) -> 25 | N27: =IF(I27>0,I27-C27,0) -> 93
B28: Mayo | C28: 45056 | D28: Abril Vallejo Villegas | E28: Transición | G28: SI | H28: 45684 | J28: No admitida | L28: =IF(H28>0,H28-C28,0) -> 628 | M28: =IF(I28>0,I28-H28,0) -> 0 | N28: =IF(I28>0,I28-C28,0) -> 0
B29: Mayo | C29: 45056 | D29: Miranda Rodríguez | E29: Transición | G29: SI | H29: 45117 | I29: 45138 | L29: =IF(H29>0,H29-C29,0) -> 61 | M29: =IF(I29>0,I29-H29,0) -> 21 | N29: =IF(I29>0,I29-C29,0) -> 82
B30: Mayo | C30: 45058 | D30: Juan Felipe Gómez Uribe | E30: Transición | G30: NO | L30: =IF(H30>0,H30-C30,0) -> 0 | M30: =IF(I30>0,I30-H30,0) -> 0 | N30: =IF(I30>0,I30-C30,0) -> 0
B31: Mayo | C31: 45070 | D31: Martina Álvarez | E31: Jardín | G31: NO | L31: =IF(H31>0,H31-C31,0) -> 0 | M31: =IF(I31>0,I31-H31,0) -> 0 | N31: =IF(I31>0,I31-C31,0) -> 0
B32: Mayo | C32: 45070 | D32: Fabiana Álvarez | E32: Prejardín | G32: NO | L32: =IF(H32>0,H32-C32,0) -> 0 | M32: =IF(I32>0,I32-H32,0) -> 0 | N32: =IF(I32>0,I32-C32,0) -> 0
B33: Mayo | C33: 45070 | D33: Emilia Jaramillo Arroyave | E33: Prejardín | G33: NO | L33: =IF(H33>0,H33-C33,0) -> 0 | M33: =IF(I33>0,I33-H33,0) -> 0 | N33: =IF(I33>0,I33-C33,0) -> 0
B34: Junio | C34: 45093 | D34: Agustín Ospina | E34: Jardín | G34: NO | L34: =IF(H34>0,H34-C34,0) -> 0 | M34: =IF(I34>0,I34-H34,0) -> 0 | N34: =IF(I34>0,I34-C34,0) -> 0
B35: Junio | C35: 45098 | D35: Agustín Giraldo Jaramillo | E35: Prejardín | G35: NO | L35: =IF(H35>0,H35-C35,0) -> 0 | M35: =IF(I35>0,I35-H35,0) -> 0 | N35: =IF(I35>0,I35-C35,0) -> 0
B36: Junio | C36: 45098 | D36: Celeste Vélez Ramírez | E36: Prejardín | G36: NO | L36: =IF(H36>0,H36-C36,0) -> 0 | M36: =IF(I36>0,I36-H36,0) -> 0 | N36: =IF(I36>0,I36-C36,0) -> 0
B37: Junio | C37: 45098 | D37: Santiago Contreras | E37: Prejardín | G37: NO | L37: =IF(H37>0,H37-C37,0) -> 0 | M37: =IF(I37>0,I37-H37,0) -> 0 | N37: =IF(I37>0,I37-C37,0) -> 0
B38: Julio | C38: 45126 | D38: Helena Osorio Ascuntar | E38: Transición | G38: NO | L38: =IF(H38>0,H38-C38,0) -> 0 | M38: =IF(I38>0,I38-H38,0) -> 0 | N38: =IF(I38>0,I38-C38,0) -> 0
B39: Julio | C39: 45126 | D39: Juan Martín Isaza | E39: Jardín | G39: NO | L39: =IF(H39>0,H39-C39,0) -> 0 | M39: =IF(I39>0,I39-H39,0) -> 0 | N39: =IF(I39>0,I39-C39,0) -> 0
B40: Julio | C40: 45126 | D40: Isabella Usme | E40: Transición | G40: NO | L40: =IF(H40>0,H40-C40,0) -> 0 | M40: =IF(I40>0,I40-H40,0) -> 0 | N40: =IF(I40>0,I40-C40,0) -> 0
...

Sheet Datos Primaria
B1: Mes | C1: Día | D1: Estudiante | E1: Grado | F1: Como conoció el colegio | G1: Inicio proceso | H1: Pruebas | I1: Observación | J1: Matrícula | K1: Estado del proceso | L1: Observaciones | M1: Días entre cita de info e inicio de pruebas | N1: Días entre pruebas y observa | O1: Días entre inici de observa y matrícula | P1: Días entre cita de info y matrícula | Q1: =AVERAGEIF(M2:M896,">0",M2:M896) -> 54.5 | R1: =AVERAGEIF(N2:N896,">0",N2:N896) -> 22.071429 | S1: =AVERAGEIF(O2:O896,">0",O2:O896) -> 51.510204 | T1: =AVERAGEIF(P2:P896,">0",P2:P896) -> 120.04082 | V1: =AVERAGEIF(P2:P896,">0",M2:M896) -> 12.367347 | W1: =AVERAGEIF(P2:P896,">0",N2:N896) -> 6.1632653 | X1: =AVERAGEIF(P2:P896,">0",O2:O896) -> 51.510204 | Y1: =AVERAGEIF(P2:P896,">0",P2:P896) -> 120.04082
B2: Enero | C2: 44939 | D2: Salome Alvarez | E2: 4° | G2: NO | M2: =IF(H2>0,H2-C2,0) -> 0 | N2: =IF(H2>0,IF(I2>0,I2-H2,0),0) -> 0 | O2: =IF(J2>0,J2-I2,0) -> 0 | P2: =IF(J2>0,J2-C2,0) -> 0
B3: Enero | C3: 44946 | D3: Samuel Santiesteban Bernal | E3: 3° | G3: NO | M3: =IF(H3>0,H3-C3,0) -> 0 | N3: =IF(H3>0,IF(I3>0,I3-H3,0),0) -> 0 | O3: =IF(J3>0,J3-I3,0) -> 0 | P3: =IF(J3>0,J3-C3,0) -> 0
B4: Enero | C4: 44946 | D4: Felipe Canel Rubio | E4: 3° | G4: SI | I4: 45124 | J4: 45146 | M4: =IF(H4>0,H4-C4,0) -> 0 | N4: =IF(H4>0,IF(I4>0,I4-H4,0),0) -> 0 | O4: =IF(J4>0,J4-I4,0) -> 22 | P4: =IF(J4>0,J4-C4,0) -> 200
B5: Enero | C5: 44946 | D5: Sara Canel Rubio | E5: 1° | G5: SI | I5: 45124 | J5: 45146 | M5: =IF(H5>0,H5-C5,0) -> 0 | N5: =IF(H5>0,IF(I5>0,I5-H5,0),0) -> 0 | O5: =IF(J5>0,J5-I5,0) -> 22 | P5: =IF(J5>0,J5-C5,0) -> 200
B6: Enero | C6: 44946 | D6: Isabella Ayala | E6: 2° | G6: NO | M6: =IF(H6>0,H6-C6,0) -> 0 | N6: =IF(H6>0,IF(I6>0,I6-H6,0),0) -> 0 | O6: =IF(J6>0,J6-I6,0) -> 0 | P6: =IF(J6>0,J6-C6,0) -> 0
B7: Enero | C7: 44946 | D7: Maria Angel Sepulveda | E7: 1° | G7: NO | M7: =IF(H7>0,H7-C7,0) -> 0 | N7: =IF(H7>0,IF(I7>0,I7-H7,0),0) -> 0 | O7: =IF(J7>0,J7-I7,0) -> 0 | P7: =IF(J7>0,J7-C7,0) -> 0
B8: Enero | C8: 44946 | D8: Jerónimo Neira Gómez. | E8: 5° | G8: NO | M8: =IF(H8>0,H8-C8,0) -> 0 | N8: =IF(H8>0,IF(I8>0,I8-H8,0),0) -> 0 | O8: =IF(J8>0,J8-I8,0) -> 0 | P8: =IF(J8>0,J8-C8,0) -> 0
B9: Enero | C9: 44953 | D9: Luciana Vásquez baena | E9: 3° | G9: NO | M9: =IF(H9>0,H9-C9,0) -> 0 | N9: =IF(H9>0,IF(I9>0,I9-H9,0),0) -> 0 | O9: =IF(J9>0,J9-I9,0) -> 0 | P9: =IF(J9>0,J9-C9,0) -> 0
B10: Enero | C10: 44953 | D10: María Antonia Méndez | E10: 3° | G10: NO | M10: =IF(H10>0,H10-C10,0) -> 0 | N10: =IF(H10>0,IF(I10>0,I10-H10,0),0) -> 0 | O10: =IF(J10>0,J10-I10,0) -> 0 | P10: =IF(J10>0,J10-C10,0) -> 0
B11: Febrero | C11: 44959 | D11: Sara Suárez | E11: 5° | G11: NO | M11: =IF(H11>0,H11-C11,0) -> 0 | N11: =IF(H11>0,IF(I11>0,I11-H11,0),0) -> 0 | O11: =IF(J11>0,J11-I11,0) -> 0 | P11: =IF(J11>0,J11-C11,0) -> 0
B12: Febrero | C12: 44974 | D12: Matias Lopez Salazar | E12: 5° | G12: NO | M12: =IF(H12>0,H12-C12,0) -> 0 | N12: =IF(H12>0,IF(I12>0,I12-H12,0),0) -> 0 | O12: =IF(J12>0,J12-I12,0) -> 0 | P12: =IF(J12>0,J12-C12,0) -> 0
B13: Febrero | C13: 44974 | D13: Ariana Espinal | E13: 4° | G13: NO | M13: =IF(H13>0,H13-C13,0) -> 0 | N13: =IF(H13>0,IF(I13>0,I13-H13,0),0) -> 0 | O13: =IF(J13>0,J13-I13,0) -> 0 | P13: =IF(J13>0,J13-C13,0) -> 0
B14: Febrero | C14: 44967 | D14: Agustin Castaño Giraldo | E14: 1° | G14: NO | M14: =IF(H14>0,H14-C14,0) -> 0 | N14: =IF(H14>0,IF(I14>0,I14-H14,0),0) -> 0 | O14: =IF(J14>0,J14-I14,0) -> 0 | P14: =IF(J14>0,J14-C14,0) -> 0
B15: Febrero | C15: 44981 | D15: Emilio Villada | E15: 5° | G15: SI | H15: 44993 | I15: 45006 | J15: 45048 | M15: =IF(H15>0,H15-C15,0) -> 12 | N15: =IF(H15>0,IF(I15>0,I15-H15,0),0) -> 13 | O15: =IF(J15>0,J15-I15,0) -> 42 | P15: =IF(J15>0,J15-C15,0) -> 67
B16: Marzo | C16: 45014 | D16: Antonio Hoyos Cruz | E16: 1° | G16: NO | M16: =IF(H16>0,H16-C16,0) -> 0 | N16: =IF(H16>0,IF(I16>0,I16-H16,0),0) -> 0 | O16: =IF(J16>0,J16-I16,0) -> 0 | P16: =IF(J16>0,J16-C16,0) -> 0
B17: Marzo | C17: 45015 | D17: Felipe Arango Escobar | E17: 2° | G17: NO | M17: =IF(H17>0,H17-C17,0) -> 0 | N17: =IF(H17>0,IF(I17>0,I17-H17,0),0) -> 0 | O17: =IF(J17>0,J17-I17,0) -> 0 | P17: =IF(J17>0,J17-C17,0) -> 0
B18: Abril | C18: 45028 | D18: Nicolás Restrepo Escobar | E18: 3° | G18: SI | I18: 45090 | J18: 45138 | M18: =IF(H18>0,H18-C18,0) -> 0 | N18: =IF(H18>0,IF(I18>0,I18-H18,0),0) -> 0 | O18: =IF(J18>0,J18-I18,0) -> 48 | P18: =IF(J18>0,J18-C18,0) -> 110
B19: Abril | C19: 45030 | D19: Sofía Bernal Henao | E19: 2° | G19: NO | M19: =IF(H19>0,H19-C19,0) -> 0 | N19: =IF(H19>0,IF(I19>0,I19-H19,0),0) -> 0 | O19: =IF(J19>0,J19-I19,0) -> 0 | P19: =IF(J19>0,J19-C19,0) -> 0
B20: Abril | C20: 45030 | D20: Amalia Ruíz García | E20: 5° | G20: NO | M20: =IF(H20>0,H20-C20,0) -> 0 | N20: =IF(H20>0,IF(I20>0,I20-H20,0),0) -> 0 | O20: =IF(J20>0,J20-I20,0) -> 0 | P20: =IF(J20>0,J20-C20,0) -> 0
B21: Abril | C21: 45030 | D21: Juan Pablo Ramírez | E21: 4° | G21: NO | M21: =IF(H21>0,H21-C21,0) -> 0 | N21: =IF(H21>0,IF(I21>0,I21-H21,0),0) -> 0 | O21: =IF(J21>0,J21-I21,0) -> 0 | P21: =IF(J21>0,J21-C21,0) -> 0
B22: Abril | C22: 45034 | D22: Liam Buririca Parra | E22: 3° | G22: NO | M22: =IF(H22>0,H22-C22,0) -> 0 | N22: =IF(H22>0,IF(I22>0,I22-H22,0),0) -> 0 | O22: =IF(J22>0,J22-I22,0) -> 0 | P22: =IF(J22>0,J22-C22,0) -> 0
B23: Abril | C23: 45037 | D23: Ian Fernández | E23: 1° | G23: SI | I23: 45040 | K23: No admitido | M23: =IF(H23>0,H23-C23,0) -> 0 | N23: =IF(H23>0,IF(I23>0,I23-H23,0),0) -> 0 | O23: =IF(J23>0,J23-I23,0) -> 0 | P23: =IF(J23>0,J23-C23,0) -> 0
B24: Mayo | C24: 45050 | D24: Luciana Arrázola | E24: 5° | G24: NO | M24: =IF(H24>0,H24-C24,0) -> 0 | N24: =IF(H24>0,IF(I24>0,I24-H24,0),0) -> 0 | O24: =IF(J24>0,J24-I24,0) -> 0 | P24: =IF(J24>0,J24-C24,0) -> 0
B25: Mayo | C25: 45058 | D25: Antonio Ríos Villegas | E25: 3° | G25: NO | M25: =IF(H25>0,H25-C25,0) -> 0 | N25: =IF(H25>0,IF(I25>0,I25-H25,0),0) -> 0 | O25: =IF(J25>0,J25-I25,0) -> 0 | P25: =IF(J25>0,J25-C25,0) -> 0
B26: Mayo | C26: 45058 | D26: Amelia Pérez Cardona | E26: 2° | G26: SI | I26: 45061 | J26: 45083 | M26: =IF(H26>0,H26-C26,0) -> 0 | N26: =IF(H26>0,IF(I26>0,I26-H26,0),0) -> 0 | O26: =IF(J26>0,J26-I26,0) -> 22 | P26: =IF(J26>0,J26-C26,0) -> 25
B27: Mayo | C27: 45065 | D27: Ivanna Ramírez Vélez | E27: 2° | G27: SI | I27: 45076 | J27: 45100 | M27: =IF(H27>0,H27-C27,0) -> 0 | N27: =IF(H27>0,IF(I27>0,I27-H27,0),0) -> 0 | O27: =IF(J27>0,J27-I27,0) -> 24 | P27: =IF(J27>0,J27-C27,0) -> 35
B28: Junio | C28: 45084 | D28: Valerie Maturana Ruíz | E28: 5° | G28: SI | I28: 45092 | J28: 45306 | M28: =IF(H28>0,H28-C28,0) -> 0 | N28: =IF(H28>0,IF(I28>0,I28-H28,0),0) -> 0 | O28: =IF(J28>0,J28-I28,0) -> 214 | P28: =IF(J28>0,J28-C28,0) -> 222
B29: Junio | C29: 45084 | D29: Felipe Maturana Ruíz | E29: 1° | G29: NO | M29: =IF(H29>0,H29-C29,0) -> 0 | N29: =IF(H29>0,IF(I29>0,I29-H29,0),0) -> 0 | O29: =IF(J29>0,J29-I29,0) -> 0 | P29: =IF(J29>0,J29-C29,0) -> 0
B30: Junio | C30: 45084 | D30: Isabella Zapata Arango | E30: 3° | G30: NO | M30: =IF(H30>0,H30-C30,0) -> 0 | N30: =IF(H30>0,IF(I30>0,I30-H30,0),0) -> 0 | O30: =IF(J30>0,J30-I30,0) -> 0 | P30: =IF(J30>0,J30-C30,0) -> 0
B31: Junio | C31: 45084 | D31: Guadalupe Giraldo Zuluaga | E31: 5° | G31: SI | H31: 45207 | I31: 45244 | J31: 45306 | M31: =IF(H31>0,H31-C31,0) -> 123 | N31: =IF(H31>0,IF(I31>0,I31-H31,0),0) -> 37 | O31: =IF(J31>0,J31-I31,0) -> 62 | P31: =IF(J31>0,J31-C31,0) -> 222
B32: Junio | C32: 45084 | D32: Victoria Giraldo Zuluaga | E32: 2° | G32: SI | I32: 45244 | J32: 45306 | M32: =IF(H32>0,H32-C32,0) -> 0 | N32: =IF(H32>0,IF(I32>0,I32-H32,0),0) -> 0 | O32: =IF(J32>0,J32-I32,0) -> 62 | P32: =IF(J32>0,J32-C32,0) -> 222
B33: Junio | C33: 45093 | D33: Josué Rodríguez Yepes | E33: 4° | G33: SI | I33: 45118 | J33: 45231 | M33: =IF(H33>0,H33-C33,0) -> 0 | N33: =IF(H33>0,IF(I33>0,I33-H33,0),0) -> 0 | O33: =IF(J33>0,J33-I33,0) -> 113 | P33: =IF(J33>0,J33-C33,0) -> 138
B34: Junio | C34: 45093 | D34: Julieta Ospina | E34: 5° | G34: NO | M34: =IF(H34>0,H34-C34,0) -> 0 | N34: =IF(H34>0,IF(I34>0,I34-H34,0),0) -> 0 | O34: =IF(J34>0,J34-I34,0) -> 0 | P34: =IF(J34>0,J34-C34,0) -> 0
B35: Junio | C35: 45100 | D35: Ian Canizales Steel | E35: 3° | G35: NO | M35: =IF(H35>0,H35-C35,0) -> 0 | N35: =IF(H35>0,IF(I35>0,I35-H35,0),0) -> 0 | O35: =IF(J35>0,J35-I35,0) -> 0 | P35: =IF(J35>0,J35-C35,0) -> 0
B36: Junio | C36: 45100 | D36: Emma Labrador Medina | E36: 1° | G36: SI | I36: 45138 | J36: 45161 | M36: =IF(H36>0,H36-C36,0) -> 0 | N36: =IF(H36>0,IF(I36>0,I36-H36,0),0) -> 0 | O36: =IF(J36>0,J36-I36,0) -> 23 | P36: =IF(J36>0,J36-C36,0) -> 61
B37: Junio | C37: 45100 | D37: Thiago Labrador Medina | E37: 2° | G37: SI | I37: 45138 | J37: 45161 | M37: =IF(H37>0,H37-C37,0) -> 0 | N37: =IF(H37>0,IF(I37>0,I37-H37,0),0) -> 0 | O37: =IF(J37>0,J37-I37,0) -> 23 | P37: =IF(J37>0,J37-C37,0) -> 61
B38: Junio | C38: 45100 | D38: Jacobo Prieto Espinal | E38: 1° | G38: NO | M38: =IF(H38>0,H38-C38,0) -> 0 | N38: =IF(H38>0,IF(I38>0,I38-H38,0),0) -> 0 | O38: =IF(J38>0,J38-I38,0) -> 0 | P38: =IF(J38>0,J38-C38,0) -> 0
B39: Julio | C39: 45113 | D39: Juan Diego Restrepo Molina | E39: 5° | G39: NO | M39: =IF(H39>0,H39-C39,0) -> 0 | N39: =IF(H39>0,IF(I39>0,I39-H39,0),0) -> 0 | O39: =IF(J39>0,J39-I39,0) -> 0 | P39: =IF(J39>0,J39-C39,0) -> 0
B40: Julio | C40: 45114 | D40: Andrés Felipe Cassiano Sandoval | E40: 5° | G40: SI | H40: 45126 | I40: 45138 | J40: 45167 | M40: =IF(H40>0,H40-C40,0) -> 12 | N40: =IF(H40>0,IF(I40>0,I40-H40,0),0) -> 12 | O40: =IF(J40>0,J40-I40,0) -> 29 | P40: =IF(J40>0,J40-C40,0) -> 53
...

Sheet Datos Bachillerato
B1: Mes | C1: Día | D1: Estudiante | E1: Grado | F1: Como conoció el colegio | G1: Inicio proceso | H1: Pruebas | I1: Observación | J1: Matricula | K1: Estado del proceso | L1: Observaciones | M1: Días entre cita de info e inicio de pruebas | N1: Días entre pruebas y observa | O1: Días entre inici de observa y matrícula | P1: Días entre cita de info y matrícula | Q1: =AVERAGEIF(M2:M901,">0",M2:M901) -> 36.258741 | R1: =AVERAGEIF(N2:N901,">0",N2:N901) -> 27.963964 | S1: =AVERAGEIF(O2:O901,">0",O2:O901) -> 43.215385 | T1: =AVERAGEIF(P2:P901,">0",P2:P901) -> 109.84615
B2: Enero | C2: 44938 | D2: Gabriela Rodríguez | E2: 8° | G2: SI | H2: 44945 | M2: =IF(H2>0,H2-C2,0) -> 7 | N2: =IF(I2>0,I2-H2,0) -> 0 | O2: =IF(J2>0,J2-I2,0) -> 0 | P2: =IF(J2>0,J2-C2,0) -> 0
B3: Enero | C3: 44938 | D3: Maria Clara Suárez | E3: 11° | G3: SI | H3: 44943 | I3: 44956 | J3: 44980 | M3: =IF(H3>0,H3-C3,0) -> 5 | N3: =IF(I3>0,I3-H3,0) -> 13 | O3: =IF(J3>0,J3-I3,0) -> 24 | P3: =IF(J3>0,J3-C3,0) -> 42
B4: Enero | C4: 44938 | D4: Esteban Yepes Franco | E4: 9° | G4: SI | H4: 44942 | I4: 44950 | M4: =IF(H4>0,H4-C4,0) -> 4 | N4: =IF(I4>0,I4-H4,0) -> 8 | O4: =IF(J4>0,J4-I4,0) -> 0 | P4: =IF(J4>0,J4-C4,0) -> 0
B5: Enero | C5: 44938 | D5: Jerónimo Ospina Palacio | E5: 8° | G5: SI | H5: 44942 | I5: 44977 | K5: No admitido | M5: =IF(H5>0,H5-C5,0) -> 4 | N5: =IF(I5>0,I5-H5,0) -> 35 | O5: =IF(J5>0,J5-I5,0) -> 0 | P5: =IF(J5>0,J5-C5,0) -> 0
B6: Enero | C6: 44938 | D6: Alegra Aponte Montoya | E6: 6° | G6: SI | H6: 44945 | I6: 44957 | J6: 44970 | M6: =IF(H6>0,H6-C6,0) -> 7 | N6: =IF(I6>0,I6-H6,0) -> 12 | O6: =IF(J6>0,J6-I6,0) -> 13 | P6: =IF(J6>0,J6-C6,0) -> 32
B7: Enero | C7: 44938 | D7: Jerónimo Gómez Moncada | E7: 6° | G7: NO | M7: =IF(H7>0,H7-C7,0) -> 0 | N7: =IF(I7>0,I7-H7,0) -> 0 | O7: =IF(J7>0,J7-I7,0) -> 0 | P7: =IF(J7>0,J7-C7,0) -> 0
B8: Enero | C8: 44938 | D8: Maria José Tapasco Quintero | E8: 7° | G8: NO | M8: =IF(H8>0,H8-C8,0) -> 0 | N8: =IF(I8>0,I8-H8,0) -> 0 | O8: =IF(J8>0,J8-I8,0) -> 0 | P8: =IF(J8>0,J8-C8,0) -> 0
B9: Enero | C9: 44945 | D9: Sasha Figueroa | E9: 11° | G9: SI | H9: 44953 | I9: 44957 | K9: No admitido | M9: =IF(H9>0,H9-C9,0) -> 8 | N9: =IF(I9>0,I9-H9,0) -> 4 | O9: =IF(J9>0,J9-I9,0) -> 0 | P9: =IF(J9>0,J9-C9,0) -> 0
B10: Enero | C10: 44945 | D10: Matias Vallejo Aguilera | E10: 7° | G10: SI | H10: 44949 | I10: 44970 | J10: 45006 | M10: =IF(H10>0,H10-C10,0) -> 4 | N10: =IF(I10>0,I10-H10,0) -> 21 | O10: =IF(J10>0,J10-I10,0) -> 36 | P10: =IF(J10>0,J10-C10,0) -> 61
B11: Enero | C11: 44945 | D11: Gabriela Patiño Sánchez | E11: 7° | G11: SI | H11: 44950 | I11: 44959 | J11: 44971 | M11: =IF(H11>0,H11-C11,0) -> 5 | N11: =IF(I11>0,I11-H11,0) -> 9 | O11: =IF(J11>0,J11-I11,0) -> 12 | P11: =IF(J11>0,J11-C11,0) -> 26
B12: Enero | C12: 44945 | D12: Alejandro Rojas Montes | E12: 11° | G12: NO | M12: =IF(H12>0,H12-C12,0) -> 0 | N12: =IF(I12>0,I12-H12,0) -> 0 | O12: =IF(J12>0,J12-I12,0) -> 0 | P12: =IF(J12>0,J12-C12,0) -> 0
B13: Enero | C13: 44945 | D13: Antonella Valencia | E13: 9° | G13: NO | M13: =IF(H13>0,H13-C13,0) -> 0 | N13: =IF(I13>0,I13-H13,0) -> 0 | O13: =IF(J13>0,J13-I13,0) -> 0 | P13: =IF(J13>0,J13-C13,0) -> 0
B14: Enero | C14: 44945 | D14: Maria Camila Díaz | E14: 8° | G14: SI | H14: 44945 | I14: 44963 | M14: =IF(H14>0,H14-C14,0) -> 0 | N14: =IF(I14>0,I14-H14,0) -> 18 | O14: =IF(J14>0,J14-I14,0) -> 0 | P14: =IF(J14>0,J14-C14,0) -> 0
B15: Enero | C15: 44945 | D15: luciana Restrepo Walker | E15: 10° | G15: SI | H15: 44945 | I15: 44994 | K15: No admitida | M15: =IF(H15>0,H15-C15,0) -> 0 | N15: =IF(I15>0,I15-H15,0) -> 49 | O15: =IF(J15>0,J15-I15,0) -> 0 | P15: =IF(J15>0,J15-C15,0) -> 0
B16: Enero | C16: 44945 | D16: Maria Valentina Muñoz Muñoz | E16: 10° | G16: NO | M16: =IF(H16>0,H16-C16,0) -> 0 | N16: =IF(I16>0,I16-H16,0) -> 0 | O16: =IF(J16>0,J16-I16,0) -> 0 | P16: =IF(J16>0,J16-C16,0) -> 0
B17: Enero | C17: 44945 | D17: Enrique Braidy | E17: 7° | G17: NO | M17: =IF(H17>0,H17-C17,0) -> 0 | N17: =IF(I17>0,I17-H17,0) -> 0 | O17: =IF(J17>0,J17-I17,0) -> 0 | P17: =IF(J17>0,J17-C17,0) -> 0
B18: Enero | C18: 44952 | D18: Pedro Juan Cespedes | E18: 8° | G18: NO | M18: =IF(H18>0,H18-C18,0) -> 0 | N18: =IF(I18>0,I18-H18,0) -> 0 | O18: =IF(J18>0,J18-I18,0) -> 0 | P18: =IF(J18>0,J18-C18,0) -> 0
B19: Enero | C19: 44952 | D19: Amalia Jimenez Sanin | E19: 6° | G19: NO | M19: =IF(H19>0,H19-C19,0) -> 0 | N19: =IF(I19>0,I19-H19,0) -> 0 | O19: =IF(J19>0,J19-I19,0) -> 0 | P19: =IF(J19>0,J19-C19,0) -> 0
B20: Febrero | C20: 44959 | D20: María José Marulanda Fiscó | E20: 8° | G20: NO | M20: =IF(H20>0,H20-C20,0) -> 0 | N20: =IF(I20>0,I20-H20,0) -> 0 | O20: =IF(J20>0,J20-I20,0) -> 0 | P20: =IF(J20>0,J20-C20,0) -> 0
B21: Febrero | C21: 44959 | D21: Manuel Torres | E21: 9° | G21: NO | M21: =IF(H21>0,H21-C21,0) -> 0 | N21: =IF(I21>0,I21-H21,0) -> 0 | O21: =IF(J21>0,J21-I21,0) -> 0 | P21: =IF(J21>0,J21-C21,0) -> 0
B22: Febrero | C22: 44959 | D22: Andrea Carolina Verbel | E22: 10° | G22: NO | M22: =IF(H22>0,H22-C22,0) -> 0 | N22: =IF(I22>0,I22-H22,0) -> 0 | O22: =IF(J22>0,J22-I22,0) -> 0 | P22: =IF(J22>0,J22-C22,0) -> 0
B23: Febrero | C23: 44959 | D23: Manuela Velez olarte | E23: 8° | G23: NO | M23: =IF(H23>0,H23-C23,0) -> 0 | N23: =IF(I23>0,I23-H23,0) -> 0 | O23: =IF(J23>0,J23-I23,0) -> 0 | P23: =IF(J23>0,J23-C23,0) -> 0
B24: Febrero | C24: 44959 | D24: Martina Velez olarte | E24: 6° | G24: NO | M24: =IF(H24>0,H24-C24,0) -> 0 | N24: =IF(I24>0,I24-H24,0) -> 0 | O24: =IF(J24>0,J24-I24,0) -> 0 | P24: =IF(J24>0,J24-C24,0) -> 0
B25: Febrero | C25: 44966 | D25: Daniel Vélez | E25: 10° | G25: NO | M25: =IF(H25>0,H25-C25,0) -> 0 | N25: =IF(I25>0,I25-H25,0) -> 0 | O25: =IF(J25>0,J25-I25,0) -> 0 | P25: =IF(J25>0,J25-C25,0) -> 0
B26: Febrero | C26: 44966 | D26: Matías López | E26: 6° | G26: NO | M26: =IF(H26>0,H26-C26,0) -> 0 | N26: =IF(I26>0,I26-H26,0) -> 0 | O26: =IF(J26>0,J26-I26,0) -> 0 | P26: =IF(J26>0,J26-C26,0) -> 0
B27: Febrero | C27: 44966 | D27: Isabel Restrepo Botero | E27: 6° | G27: SI | H27: 44966 | I27: 44991 | J27: 45146 | M27: =IF(H27>0,H27-C27,0) -> 0 | N27: =IF(I27>0,I27-H27,0) -> 25 | O27: =IF(J27>0,J27-I27,0) -> 155 | P27: =IF(J27>0,J27-C27,0) -> 180
B28: Febrero | C28: 44966 | D28: Miguel SantaMaria Valencia | E28: 10° | G28: NO | M28: =IF(H28>0,H28-C28,0) -> 0 | N28: =IF(I28>0,I28-H28,0) -> 0 | O28: =IF(J28>0,J28-I28,0) -> 0 | P28: =IF(J28>0,J28-C28,0) -> 0
B29: Febrero | C29: 44973 | D29: Ahinoa Rondon | E29: 6° | G29: SI | H29: 44986 | I29: 44999 | J29: 45013 | M29: =IF(H29>0,H29-C29,0) -> 13 | N29: =IF(I29>0,I29-H29,0) -> 13 | O29: =IF(J29>0,J29-I29,0) -> 14 | P29: =IF(J29>0,J29-C29,0) -> 40
B30: Febrero | C30: 44973 | D30: Juan Pablo caraballo | E30: 10° | G30: SI | H30: 44978 | I30: 45026 | J30: 45050 | M30: =IF(H30>0,H30-C30,0) -> 5 | N30: =IF(I30>0,I30-H30,0) -> 48 | O30: =IF(J30>0,J30-I30,0) -> 24 | P30: =IF(J30>0,J30-C30,0) -> 77
B31: Febrero | C31: 44973 | D31: Sofia Molina Hoyos | E31: 8° | G31: NO | M31: =IF(H31>0,H31-C31,0) -> 0 | N31: =IF(I31>0,I31-H31,0) -> 0 | O31: =IF(J31>0,J31-I31,0) -> 0 | P31: =IF(J31>0,J31-C31,0) -> 0
B32: Febrero | C32: 44980 | D32: Juan Sebastián Serna Guarin | E32: 10° | G32: SI | H32: 44984 | M32: =IF(H32>0,H32-C32,0) -> 4 | N32: =IF(I32>0,I32-H32,0) -> 0 | O32: =IF(J32>0,J32-I32,0) -> 0 | P32: =IF(J32>0,J32-C32,0) -> 0
B33: Febrero | C33: 44980 | D33: Ian Dicson Salazar | E33: 8° | G33: NO | M33: =IF(H33>0,H33-C33,0) -> 0 | N33: =IF(I33>0,I33-H33,0) -> 0 | O33: =IF(J33>0,J33-I33,0) -> 0 | P33: =IF(J33>0,J33-C33,0) -> 0
B34: Febrero | C34: 44980 | D34: Juan Jacobo García Montoya | E34: 6° | G34: NO | M34: =IF(H34>0,H34-C34,0) -> 0 | N34: =IF(I34>0,I34-H34,0) -> 0 | O34: =IF(J34>0,J34-I34,0) -> 0 | P34: =IF(J34>0,J34-C34,0) -> 0
B35: Febrero | C35: 44980 | D35: Valerio Yafreda | E35: 7° | G35: NO | M35: =IF(H35>0,H35-C35,0) -> 0 | N35: =IF(I35>0,I35-H35,0) -> 0 | O35: =IF(J35>0,J35-I35,0) -> 0 | P35: =IF(J35>0,J35-C35,0) -> 0
B36: Marzo | C36: 44987 | D36: Samuel espitia Cardozo | E36: 8° | G36: NO | M36: =IF(H36>0,H36-C36,0) -> 0 | N36: =IF(I36>0,I36-H36,0) -> 0 | O36: =IF(J36>0,J36-I36,0) -> 0 | P36: =IF(J36>0,J36-C36,0) -> 0
B37: Marzo | C37: 44987 | D37: Emilio Vásquez Yepes | E37: 11° | G37: SI | H37: 44992 | M37: =IF(H37>0,H37-C37,0) -> 5 | N37: =IF(I37>0,I37-H37,0) -> 0 | O37: =IF(J37>0,J37-I37,0) -> 0 | P37: =IF(J37>0,J37-C37,0) -> 0
B38: Marzo | C38: 44987 | D38: Juan Sebastian Pulgarín | E38: 9° | G38: SI | H38: 45143 | I38: 45313 | K38: No admitido | M38: =IF(H38>0,H38-C38,0) -> 156 | N38: =IF(I38>0,I38-H38,0) -> 170 | O38: =IF(J38>0,J38-I38,0) -> 0 | P38: =IF(J38>0,J38-C38,0) -> 0
B39: Marzo | C39: 44994 | D39: Simón Aguirre | E39: 7° | G39: NO | M39: =IF(H39>0,H39-C39,0) -> 0 | N39: =IF(I39>0,I39-H39,0) -> 0 | O39: =IF(J39>0,J39-I39,0) -> 0 | P39: =IF(J39>0,J39-C39,0) -> 0
B40: Marzo | C40: 44994 | D40: Angelina Wengert | E40: 10° | G40: NO | M40: =IF(H40>0,H40-C40,0) -> 0 | N40: =IF(I40>0,I40-H40,0) -> 0 | O40: =IF(J40>0,J40-I40,0) -> 0 | P40: =IF(J40>0,J40-C40,0) -> 0
...

Sheet Preescolar
B1: Citas de información por mes | I1: Citas de información acumulado por año | P1: Citas de información acumulado todos los años
B2: MES | C2: Prejardín | D2: Jardín | E2: Transición | F2: TOTAL | I2: MES | J2: Prejardín | K2: Jardín | L2: Transición | M2: TOTAL | P2: MES | Q2: Prejardín | R2: Jardín | S2: Transición | T2: TOTAL
A3: 2023 | B3: Enero | C3: =COUNTIFS('Datos Preescolar'!$E:$E,C$2,'Datos Preescolar'!$C:$C,">=01/01/2023",'Datos Preescolar'!$C:$C,"<=31/01/2023") -> 5 | D3: =COUNTIFS('Datos Preescolar'!$E:$E,D$2,'Datos Preescolar'!$C:$C,">=01/01/2023",'Datos Preescolar'!$C:$C,"<=31/01/2023") -> 0 | E3: =COUNTIFS('Datos Preescolar'!$E:$E,E$2,'Datos Preescolar'!$C:$C,">=01/01/2023",'Datos Preescolar'!$C:$C,"<=31/01/2023") -> 1 | F3: =SUM(C3:E3) -> 6 | H3: =A3 -> 2023 | I3: Enero | J3: =SUM(C$3:C3) -> 5 | K3: =SUM(D$3:D3) -> 0 | L3: =SUM(E$3:E3) -> 1 | M3: =SUM(J3:L3) -> 6 | O3: =A3 -> 2023 | P3: Enero | Q3: =SUM(C$3:C3) -> 5 | R3: =SUM(D$3:D3) -> 0 | S3: =SUM(E$3:E3) -> 1 | T3: =SUM(Q3:S3) -> 6
B4: Febrero | C4: =COUNTIFS('Datos Preescolar'!$E:$E,C$2,'Datos Preescolar'!$C:$C,">=01/02/2023",'Datos Preescolar'!$C:$C,"<=28/02/2023") -> 4 | D4: =COUNTIFS('Datos Preescolar'!$E:$E,D$2,'Datos Preescolar'!$C:$C,">=01/02/2023",'Datos Preescolar'!$C:$C,"<=28/02/2023") -> 1 | E4: =COUNTIFS('Datos Preescolar'!$E:$E,E$2,'Datos Preescolar'!$C:$C,">=01/02/2023",'Datos Preescolar'!$C:$C,"<=28/02/2023") -> 2 | F4: =SUM(C4:E4) -> 7 | I4: Febrero | J4: =SUM(C$3:C4) -> 9 | K4: =SUM(D$3:D4) -> 1 | L4: =SUM(E$3:E4) -> 3 | M4: =SUM(J4:L4) -> 13 | P4: Febrero | Q4: =SUM(C$3:C4) -> 9 | R4: =SUM(D$3:D4) -> 1 | S4: =SUM(E$3:E4) -> 3 | T4: =SUM(Q4:S4) -> 13
B5: Marzo | C5: =COUNTIFS('Datos Preescolar'!$E:$E,C$2,'Datos Preescolar'!$C:$C,">=01/03/2023",'Datos Preescolar'!$C:$C,"<=31/03/2023") -> 0 | D5: =COUNTIFS('Datos Preescolar'!$E:$E,D$2,'Datos Preescolar'!$C:$C,">=01/03/2023",'Datos Preescolar'!$C:$C,"<=31/03/2023") -> 0 | E5: =COUNTIFS('Datos Preescolar'!$E:$E,E$2,'Datos Preescolar'!$C:$C,">=01/03/2023",'Datos Preescolar'!$C:$C,"<=31/03/2023") -> 3 | F5: =SUM(C5:E5) -> 3 | I5: Marzo | J5: =SUM(C$3:C5) -> 9 | K5: =SUM(D$3:D5) -> 1 | L5: =SUM(E$3:E5) -> 6 | M5: =SUM(J5:L5) -> 16 | P5: Marzo | Q5: =SUM(C$3:C5) -> 9 | R5: =SUM(D$3:D5) -> 1 | S5: =SUM(E$3:E5) -> 6 | T5: =SUM(Q5:S5) -> 16
B6: Abril | C6: =COUNTIFS('Datos Preescolar'!$E:$E,C$2,'Datos Preescolar'!$C:$C,">=01/04/2023",'Datos Preescolar'!$C:$C,"<=30/04/2023") -> 6 | D6: =COUNTIFS('Datos Preescolar'!$E:$E,D$2,'Datos Preescolar'!$C:$C,">=01/04/2023",'Datos Preescolar'!$C:$C,"<=30/04/2023") -> 2 | E6: =COUNTIFS('Datos Preescolar'!$E:$E,E$2,'Datos Preescolar'!$C:$C,">=01/04/2023",'Datos Preescolar'!$C:$C,"<=30/04/2023") -> 0 | F6: =SUM(C6:E6) -> 8 | I6: Abril | J6: =SUM(C$3:C6) -> 15 | K6: =SUM(D$3:D6) -> 3 | L6: =SUM(E$3:E6) -> 6 | M6: =SUM(J6:L6) -> 24 | P6: Abril | Q6: =SUM(C$3:C6) -> 15 | R6: =SUM(D$3:D6) -> 3 | S6: =SUM(E$3:E6) -> 6 | T6: =SUM(Q6:S6) -> 24
B7: Mayo | C7: =COUNTIFS('Datos Preescolar'!$E:$E,C$2,'Datos Preescolar'!$C:$C,">=01/05/2023",'Datos Preescolar'!$C:$C,"<=31/05/2023") -> 3 | D7: =COUNTIFS('Datos Preescolar'!$E:$E,D$2,'Datos Preescolar'!$C:$C,">=01/05/2023",'Datos Preescolar'!$C:$C,"<=31/05/2023") -> 2 | E7: =COUNTIFS('Datos Preescolar'!$E:$E,E$2,'Datos Preescolar'!$C:$C,">=01/05/2023",'Datos Preescolar'!$C:$C,"<=31/05/2023") -> 3 | F7: =SUM(C7:E7) -> 8 | I7: Mayo | J7: =SUM(C$3:C7) -> 18 | K7: =SUM(D$3:D7) -> 5 | L7: =SUM(E$3:E7) -> 9 | M7: =SUM(J7:L7) -> 32 | P7: Mayo | Q7: =SUM(C$3:C7) -> 18 | R7: =SUM(D$3:D7) -> 5 | S7: =SUM(E$3:E7) -> 9 | T7: =SUM(Q7:S7) -> 32
B8: Junio | C8: =COUNTIFS('Datos Preescolar'!$E:$E,C$2,'Datos Preescolar'!$C:$C,">=01/06/2023",'Datos Preescolar'!$C:$C,"<=30/06/2023") -> 3 | D8: =COUNTIFS('Datos Preescolar'!$E:$E,D$2,'Datos Preescolar'!$C:$C,">=01/06/2023",'Datos Preescolar'!$C:$C,"<=30/06/2023") -> 1 | E8: =COUNTIFS('Datos Preescolar'!$E:$E,E$2,'Datos Preescolar'!$C:$C,">=01/06/2023",'Datos Preescolar'!$C:$C,"<=30/06/2023") -> 0 | F8: =SUM(C8:E8) -> 4 | I8: Junio | J8: =SUM(C$3:C8) -> 21 | K8: =SUM(D$3:D8) -> 6 | L8: =SUM(E$3:E8) -> 9 | M8: =SUM(J8:L8) -> 36 | P8: Junio | Q8: =SUM(C$3:C8) -> 21 | R8: =SUM(D$3:D8) -> 6 | S8: =SUM(E$3:E8) -> 9 | T8: =SUM(Q8:S8) -> 36
B9: Julio | C9: =COUNTIFS('Datos Preescolar'!$E:$E,C$2,'Datos Preescolar'!$C:$C,">=01/07/2023",'Datos Preescolar'!$C:$C,"<=31/07/2023") -> 1 | D9: =COUNTIFS('Datos Preescolar'!$E:$E,D$2,'Datos Preescolar'!$C:$C,">=01/07/2023",'Datos Preescolar'!$C:$C,"<=31/07/2023") -> 1 | E9: =COUNTIFS('Datos Preescolar'!$E:$E,E$2,'Datos Preescolar'!$C:$C,">=01/07/2023",'Datos Preescolar'!$C:$C,"<=31/07/2023") -> 3 | F9: =SUM(C9:E9) -> 5 | I9: Julio | J9: =SUM(C$3:C9) -> 22 | K9: =SUM(D$3:D9) -> 7 | L9: =SUM(E$3:E9) -> 12 | M9: =SUM(J9:L9) -> 41 | P9: Julio | Q9: =SUM(C$3:C9) -> 22 | R9: =SUM(D$3:D9) -> 7 | S9: =SUM(E$3:E9) -> 12 | T9: =SUM(Q9:S9) -> 41
B10: Agosto | C10: =COUNTIFS('Datos Preescolar'!$E:$E,C$2,'Datos Preescolar'!$C:$C,">=01/08/2023",'Datos Preescolar'!$C:$C,"<=31/08/2023") -> 2 | D10: =COUNTIFS('Datos Preescolar'!$E:$E,D$2,'Datos Preescolar'!$C:$C,">=01/08/2023",'Datos Preescolar'!$C:$C,"<=31/08/2023") -> 1 | E10: =COUNTIFS('Datos Preescolar'!$E:$E,E$2,'Datos Preescolar'!$C:$C,">=01/08/2023",'Datos Preescolar'!$C:$C,"<=31/08/2023") -> 4 | F10: =SUM(C10:E10) -> 7 | I10: Agosto | J10: =SUM(C$3:C10) -> 24 | K10: =SUM(D$3:D10) -> 8 | L10: =SUM(E$3:E10) -> 16 | M10: =SUM(J10:L10) -> 48 | P10: Agosto | Q10: =SUM(C$3:C10) -> 24 | R10: =SUM(D$3:D10) -> 8 | S10: =SUM(E$3:E10) -> 16 | T10: =SUM(Q10:S10) -> 48
B11: Septiembre | C11: =COUNTIFS('Datos Preescolar'!$E:$E,C$2,'Datos Preescolar'!$C:$C,">=01/09/2023",'Datos Preescolar'!$C:$C,"<=30/09/2023") -> 5 | D11: =COUNTIFS('Datos Preescolar'!$E:$E,D$2,'Datos Preescolar'!$C:$C,">=01/09/2023",'Datos Preescolar'!$C:$C,"<=30/09/2023") -> 0 | E11: =COUNTIFS('Datos Preescolar'!$E:$E,E$2,'Datos Preescolar'!$C:$C,">=01/09/2023",'Datos Preescolar'!$C:$C,"<=30/09/2023") -> 1 | F11: =SUM(C11:E11) -> 6 | I11: Septiembre | J11: =SUM(C$3:C11) -> 29 | K11: =SUM(D$3:D11) -> 8 | L11: =SUM(E$3:E11) -> 17 | M11: =SUM(J11:L11) -> 54 | P11: Septiembre | Q11: =SUM(C$3:C11) -> 29 | R11: =SUM(D$3:D11) -> 8 | S11: =SUM(E$3:E11) -> 17 | T11: =SUM(Q11:S11) -> 54
B12: Octubre | C12: =COUNTIFS('Datos Preescolar'!$E:$E,C$2,'Datos Preescolar'!$C:$C,">=01/10/2023",'Datos Preescolar'!$C:$C,"<=31/10/2023") -> 1 | D12: =COUNTIFS('Datos Preescolar'!$E:$E,D$2,'Datos Preescolar'!$C:$C,">=01/10/2023",'Datos Preescolar'!$C:$C,"<=31/10/2023") -> 1 | E12: =COUNTIFS('Datos Preescolar'!$E:$E,E$2,'Datos Preescolar'!$C:$C,">=01/10/2023",'Datos Preescolar'!$C:$C,"<=31/10/2023") -> 0 | F12: =SUM(C12:E12) -> 2 | I12: Octubre | J12: =SUM(C$3:C12) -> 30 | K12: =SUM(D$3:D12) -> 9 | L12: =SUM(E$3:E12) -> 17 | M12: =SUM(J12:L12) -> 56 | P12: Octubre | Q12: =SUM(C$3:C12) -> 30 | R12: =SUM(D$3:D12) -> 9 | S12: =SUM(E$3:E12) -> 17 | T12: =SUM(Q12:S12) -> 56
B13: Noviembre | C13: =COUNTIFS('Datos Preescolar'!$E:$E,C$2,'Datos Preescolar'!$C:$C,">=01/11/2023",'Datos Preescolar'!$C:$C,"<=30/11/2023") -> 0 | D13: =COUNTIFS('Datos Preescolar'!$E:$E,D$2,'Datos Preescolar'!$C:$C,">=01/11/2023",'Datos Preescolar'!$C:$C,"<=30/11/2023") -> 2 | E13: =COUNTIFS('Datos Preescolar'!$E:$E,E$2,'Datos Preescolar'!$C:$C,">=01/11/2023",'Datos Preescolar'!$C:$C,"<=30/11/2023") -> 1 | F13: =SUM(C13:E13) -> 3 | I13: Noviembre | J13: =SUM(C$3:C13) -> 30 | K13: =SUM(D$3:D13) -> 11 | L13: =SUM(E$3:E13) -> 18 | M13: =SUM(J13:L13) -> 59 | P13: Noviembre | Q13: =SUM(C$3:C13) -> 30 | R13: =SUM(D$3:D13) -> 11 | S13: =SUM(E$3:E13) -> 18 | T13: =SUM(Q13:S13) -> 59
B14: Diciembre | C14: =COUNTIFS('Datos Preescolar'!$E:$E,C$2,'Datos Preescolar'!$C:$C,">=01/12/2023",'Datos Preescolar'!$C:$C,"<=31/12/2023") -> 0 | D14: =COUNTIFS('Datos Preescolar'!$E:$E,D$2,'Datos Preescolar'!$C:$C,">=01/12/2023",'Datos Preescolar'!$C:$C,"<=31/12/2023") -> 0 | E14: =COUNTIFS('Datos Preescolar'!$E:$E,E$2,'Datos Preescolar'!$C:$C,">=01/12/2023",'Datos Preescolar'!$C:$C,"<=31/12/2023") -> 0 | F14: =SUM(C14:E14) -> 0 | I14: Diciembre | J14: =SUM(C$3:C14) -> 30 | K14: =SUM(D$3:D14) -> 11 | L14: =SUM(E$3:E14) -> 18 | M14: =SUM(J14:L14) -> 59 | P14: Diciembre | Q14: =SUM(C$3:C14) -> 30 | R14: =SUM(D$3:D14) -> 11 | S14: =SUM(E$3:E14) -> 18 | T14: =SUM(Q14:S14) -> 59
A15: 2024 | B15: Enero | C15: =COUNTIFS('Datos Preescolar'!$E:$E,C$2,'Datos Preescolar'!$C:$C,">=01/01/2024",'Datos Preescolar'!$C:$C,"<=31/01/2024") -> 2 | D15: =COUNTIFS('Datos Preescolar'!$E:$E,D$2,'Datos Preescolar'!$C:$C,">=01/01/2024",'Datos Preescolar'!$C:$C,"<=31/01/2024") -> 1 | E15: =COUNTIFS('Datos Preescolar'!$E:$E,E$2,'Datos Preescolar'!$C:$C,">=01/01/2024",'Datos Preescolar'!$C:$C,"<=31/01/2024") -> 2 | F15: =SUM(C15:E15) -> 5 | H15: =A15 -> 2024 | I15: Enero | J15: =SUM(C$15:C15) -> 2 | K15: =SUM(D$15:D15) -> 1 | L15: =SUM(E$15:E15) -> 2 | M15: =SUM(J15:L15) -> 5 | O15: =A15 -> 2024 | P15: Enero | Q15: =SUM(C$3:C15) -> 32 | R15: =SUM(D$3:D15) -> 12 | S15: =SUM(E$3:E15) -> 20 | T15: =SUM(Q15:S15) -> 64
B16: Febrero | C16: =COUNTIFS('Datos Preescolar'!$E:$E,C$2,'Datos Preescolar'!$C:$C,">=01/02/2024",'Datos Preescolar'!$C:$C,"<=29/02/2024") -> 3 | D16: =COUNTIFS('Datos Preescolar'!$E:$E,D$2,'Datos Preescolar'!$C:$C,">=01/02/2024",'Datos Preescolar'!$C:$C,"<=29/02/2024") -> 1 | E16: =COUNTIFS('Datos Preescolar'!$E:$E,E$2,'Datos Preescolar'!$C:$C,">=01/02/2024",'Datos Preescolar'!$C:$C,"<=29/02/2024") -> 0 | F16: =SUM(C16:E16) -> 4 | I16: Febrero | J16: =SUM(C$15:C16) -> 5 | K16: =SUM(D$15:D16) -> 2 | L16: =SUM(E$15:E16) -> 2 | M16: =SUM(J16:L16) -> 9 | P16: Febrero | Q16: =SUM(C$3:C16) -> 35 | R16: =SUM(D$3:D16) -> 13 | S16: =SUM(E$3:E16) -> 20 | T16: =SUM(Q16:S16) -> 68
B17: Marzo | C17: =COUNTIFS('Datos Preescolar'!$E:$E,C$2,'Datos Preescolar'!$C:$C,">=01/03/2024",'Datos Preescolar'!$C:$C,"<=31/03/2024") -> 0 | D17: =COUNTIFS('Datos Preescolar'!$E:$E,D$2,'Datos Preescolar'!$C:$C,">=01/03/2024",'Datos Preescolar'!$C:$C,"<=31/03/2024") -> 1 | E17: =COUNTIFS('Datos Preescolar'!$E:$E,E$2,'Datos Preescolar'!$C:$C,">=01/03/2024",'Datos Preescolar'!$C:$C,"<=31/03/2024") -> 0 | F17: =SUM(C17:E17) -> 1 | I17: Marzo | J17: =SUM(C$15:C17) -> 5 | K17: =SUM(D$15:D17) -> 3 | L17: =SUM(E$15:E17) -> 2 | M17: =SUM(J17:L17) -> 10 | P17: Marzo | Q17: =SUM(C$3:C17) -> 35 | R17: =SUM(D$3:D17) -> 14 | S17: =SUM(E$3:E17) -> 20 | T17: =SUM(Q17:S17) -> 69
B18: Abril | C18: =COUNTIFS('Datos Preescolar'!$E:$E,C$2,'Datos Preescolar'!$C:$C,">=01/04/2024",'Datos Preescolar'!$C:$C,"<=30/04/2024") -> 3 | D18: =COUNTIFS('Datos Preescolar'!$E:$E,D$2,'Datos Preescolar'!$C:$C,">=01/04/2024",'Datos Preescolar'!$C:$C,"<=30/04/2024") -> 2 | E18: =COUNTIFS('Datos Preescolar'!$E:$E,E$2,'Datos Preescolar'!$C:$C,">=01/04/2024",'Datos Preescolar'!$C:$C,"<=30/04/2024") -> 0 | F18: =SUM(C18:E18) -> 5 | I18: Abril | J18: =SUM(C$15:C18) -> 8 | K18: =SUM(D$15:D18) -> 5 | L18: =SUM(E$15:E18) -> 2 | M18: =SUM(J18:L18) -> 15 | P18: Abril | Q18: =SUM(C$3:C18) -> 38 | R18: =SUM(D$3:D18) -> 16 | S18: =SUM(E$3:E18) -> 20 | T18: =SUM(Q18:S18) -> 74
B19: Mayo | C19: =COUNTIFS('Datos Preescolar'!$E:$E,C$2,'Datos Preescolar'!$C:$C,">=01/05/2024",'Datos Preescolar'!$C:$C,"<=31/05/2024") -> 2 | D19: =COUNTIFS('Datos Preescolar'!$E:$E,D$2,'Datos Preescolar'!$C:$C,">=01/05/2024",'Datos Preescolar'!$C:$C,"<=31/05/2024") -> 2 | E19: =COUNTIFS('Datos Preescolar'!$E:$E,E$2,'Datos Preescolar'!$C:$C,">=01/05/2024",'Datos Preescolar'!$C:$C,"<=31/05/2024") -> 0 | F19: =SUM(C19:E19) -> 4 | I19: Mayo | J19: =SUM(C$15:C19) -> 10 | K19: =SUM(D$15:D19) -> 7 | L19: =SUM(E$15:E19) -> 2 | M19: =SUM(J19:L19) -> 19 | P19: Mayo | Q19: =SUM(C$3:C19) -> 40 | R19: =SUM(D$3:D19) -> 18 | S19: =SUM(E$3:E19) -> 20 | T19: =SUM(Q19:S19) -> 78
B20: Junio | C20: =COUNTIFS('Datos Preescolar'!$E:$E,C$2,'Datos Preescolar'!$C:$C,">=01/06/2024",'Datos Preescolar'!$C:$C,"<=30/06/2024") -> 3 | D20: =COUNTIFS('Datos Preescolar'!$E:$E,D$2,'Datos Preescolar'!$C:$C,">=01/06/2024",'Datos Preescolar'!$C:$C,"<=30/06/2024") -> 1 | E20: =COUNTIFS('Datos Preescolar'!$E:$E,E$2,'Datos Preescolar'!$C:$C,">=01/06/2024",'Datos Preescolar'!$C:$C,"<=30/06/2024") -> 1 | F20: =SUM(C20:E20) -> 5 | I20: Junio | J20: =SUM(C$15:C20) -> 13 | K20: =SUM(D$15:D20) -> 8 | L20: =SUM(E$15:E20) -> 3 | M20: =SUM(J20:L20) -> 24 | P20: Junio | Q20: =SUM(C$3:C20) -> 43 | R20: =SUM(D$3:D20) -> 19 | S20: =SUM(E$3:E20) -> 21 | T20: =SUM(Q20:S20) -> 83
B21: Julio | C21: =COUNTIFS('Datos Preescolar'!$E:$E,C$2,'Datos Preescolar'!$C:$C,">=01/07/2024",'Datos Preescolar'!$C:$C,"<=31/07/2024") -> 3 | D21: =COUNTIFS('Datos Preescolar'!$E:$E,D$2,'Datos Preescolar'!$C:$C,">=01/07/2024",'Datos Preescolar'!$C:$C,"<=31/07/2024") -> 2 | E21: 0 | F21: =SUM(C21:E21) -> 5 | I21: Julio | J21: =SUM(C$15:C21) -> 16 | K21: =SUM(D$15:D21) -> 10 | L21: =SUM(E$15:E21) -> 3 | M21: =SUM(J21:L21) -> 29 | P21: Julio | Q21: =SUM(C$3:C21) -> 46 | R21: =SUM(D$3:D21) -> 21 | S21: =SUM(E$3:E21) -> 21 | T21: =SUM(Q21:S21) -> 88
B22: Agosto | C22: =COUNTIFS('Datos Preescolar'!$E:$E,C$2,'Datos Preescolar'!$C:$C,">=01/08/2024",'Datos Preescolar'!$C:$C,"<=31/08/2024") -> 1 | D22: =COUNTIFS('Datos Preescolar'!$E:$E,D$2,'Datos Preescolar'!$C:$C,">=01/08/2024",'Datos Preescolar'!$C:$C,"<=31/08/2024") -> 0 | E22: =COUNTIFS('Datos Preescolar'!$E:$E,E$2,'Datos Preescolar'!$C:$C,">=01/08/2024",'Datos Preescolar'!$C:$C,"<=31/08/2024") -> 1 | F22: =SUM(C22:E22) -> 2 | I22: Agosto | J22: =SUM(C$15:C22) -> 17 | K22: =SUM(D$15:D22) -> 10 | L22: =SUM(E$15:E22) -> 4 | M22: =SUM(J22:L22) -> 31 | P22: Agosto | Q22: =SUM(C$3:C22) -> 47 | R22: =SUM(D$3:D22) -> 21 | S22: =SUM(E$3:E22) -> 22 | T22: =SUM(Q22:S22) -> 90
B23: Septiembre | C23: =COUNTIFS('Datos Preescolar'!$E:$E,C$2,'Datos Preescolar'!$C:$C,">=01/09/2024",'Datos Preescolar'!$C:$C,"<=30/09/2024") -> 3 | D23: =COUNTIFS('Datos Preescolar'!$E:$E,D$2,'Datos Preescolar'!$C:$C,">=01/09/2024",'Datos Preescolar'!$C:$C,"<=30/09/2024") -> 0 | E23: =COUNTIFS('Datos Preescolar'!$E:$E,E$2,'Datos Preescolar'!$C:$C,">=01/09/2024",'Datos Preescolar'!$C:$C,"<=30/09/2024") -> 0 | F23: =SUM(C23:E23) -> 3 | I23: Septiembre | J23: =SUM(C$15:C23) -> 20 | K23: =SUM(D$15:D23) -> 10 | L23: =SUM(E$15:E23) -> 4 | M23: =SUM(J23:L23) -> 34 | P23: Septiembre | Q23: =SUM(C$3:C23) -> 50 | R23: =SUM(D$3:D23) -> 21 | S23: =SUM(E$3:E23) -> 22 | T23: =SUM(Q23:S23) -> 93
B24: Octubre | C24: =COUNTIFS('Datos Preescolar'!$E:$E,C$2,'Datos Preescolar'!$C:$C,">=01/10/2024",'Datos Preescolar'!$C:$C,"<=31/10/2024") -> 1 | D24: =COUNTIFS('Datos Preescolar'!$E:$E,D$2,'Datos Preescolar'!$C:$C,">=01/10/2024",'Datos Preescolar'!$C:$C,"<=31/10/2024") -> 2 | E24: =COUNTIFS('Datos Preescolar'!$E:$E,E$2,'Datos Preescolar'!$C:$C,">=01/10/2024",'Datos Preescolar'!$C:$C,"<=31/10/2024") -> 0 | F24: =SUM(C24:E24) -> 3 | I24: Octubre | J24: =SUM(C$15:C24) -> 21 | K24: =SUM(D$15:D24) -> 12 | L24: =SUM(E$15:E24) -> 4 | M24: =SUM(J24:L24) -> 37 | P24: Octubre | Q24: =SUM(C$3:C24) -> 51 | R24: =SUM(D$3:D24) -> 23 | S24: =SUM(E$3:E24) -> 22 | T24: =SUM(Q24:S24) -> 96
B25: Noviembre | C25: =COUNTIFS('Datos Preescolar'!$E:$E,C$2,'Datos Preescolar'!$C:$C,">=01/11/2024",'Datos Preescolar'!$C:$C,"<=30/11/2024") -> 3 | D25: =COUNTIFS('Datos Preescolar'!$E:$E,D$2,'Datos Preescolar'!$C:$C,">=01/11/2024",'Datos Preescolar'!$C:$C,"<=30/11/2024") -> 1 | E25: =COUNTIFS('Datos Preescolar'!$E:$E,E$2,'Datos Preescolar'!$C:$C,">=01/11/2024",'Datos Preescolar'!$C:$C,"<=30/11/2024") -> 1 | F25: =SUM(C25:E25) -> 5 | I25: Noviembre | J25: =SUM(C$15:C25) -> 24 | K25: =SUM(D$15:D25) -> 13 | L25: =SUM(E$15:E25) -> 5 | M25: =SUM(J25:L25) -> 42 | P25: Noviembre | Q25: =SUM(C$3:C25) -> 54 | R25: =SUM(D$3:D25) -> 24 | S25: =SUM(E$3:E25) -> 23 | T25: =SUM(Q25:S25) -> 101
B26: Diciembre | C26: =COUNTIFS('Datos Preescolar'!$E:$E,C$2,'Datos Preescolar'!$C:$C,">=01/12/2024",'Datos Preescolar'!$C:$C,"<=31/12/2024") -> 2 | D26: =COUNTIFS('Datos Preescolar'!$E:$E,D$2,'Datos Preescolar'!$C:$C,">=01/12/2024",'Datos Preescolar'!$C:$C,"<=31/12/2024") -> 2 | E26: =COUNTIFS('Datos Preescolar'!$E:$E,E$2,'Datos Preescolar'!$C:$C,">=01/12/2024",'Datos Preescolar'!$C:$C,"<=31/12/2024") -> 0 | F26: =SUM(C26:E26) -> 4 | I26: Diciembre | J26: =SUM(C$15:C26) -> 26 | K26: =SUM(D$15:D26) -> 15 | L26: =SUM(E$15:E26) -> 5 | M26: =SUM(J26:L26) -> 46 | P26: Diciembre | Q26: =SUM(C$3:C26) -> 56 | R26: =SUM(D$3:D26) -> 26 | S26: =SUM(E$3:E26) -> 23 | T26: =SUM(Q26:S26) -> 105
A27: 2025 | B27: Enero | C27: =COUNTIFS('Datos Preescolar'!$E:$E,C$2,'Datos Preescolar'!$C:$C,">=01/01/2025",'Datos Preescolar'!$C:$C,"<=31/01/2025") -> 0 | D27: =COUNTIFS('Datos Preescolar'!$E:$E,D$2,'Datos Preescolar'!$C:$C,">=01/01/2025",'Datos Preescolar'!$C:$C,"<=31/01/2025") -> 1 | E27: =COUNTIFS('Datos Preescolar'!$E:$E,E$2,'Datos Preescolar'!$C:$C,">=01/01/2025",'Datos Preescolar'!$C:$C,"<=31/01/2025") -> 0 | F27: =SUM(C27:E27) -> 1 | H27: =A27 -> 2025 | I27: Enero | J27: =SUM(C$27:C27) -> 0 | K27: =SUM(D$27:D27) -> 1 | L27: =SUM(E$27:E27) -> 0 | M27: =SUM(J27:L27) -> 1 | O27: =A27 -> 2025 | P27: Enero | Q27: =SUM(C$3:C27) -> 56 | R27: =SUM(D$3:D27) -> 27 | S27: =SUM(E$3:E27) -> 23 | T27: =SUM(Q27:S27) -> 106
B28: Febrero | C28: =COUNTIFS('Datos Preescolar'!$E:$E,C$2,'Datos Preescolar'!$C:$C,">=01/02/2025",'Datos Preescolar'!$C:$C,"<=28/02/2025") -> 2 | D28: =COUNTIFS('Datos Preescolar'!$E:$E,D$2,'Datos Preescolar'!$C:$C,">=01/02/2025",'Datos Preescolar'!$C:$C,"<=28/02/2025") -> 2 | E28: =COUNTIFS('Datos Preescolar'!$E:$E,E$2,'Datos Preescolar'!$C:$C,">=01/02/2025",'Datos Preescolar'!$C:$C,"<=28/02/2025") -> 1 | F28: =SUM(C28:E28) -> 5 | I28: Febrero | J28: =SUM(C$27:C28) -> 2 | K28: =SUM(D$27:D28) -> 3 | L28: =SUM(E$27:E28) -> 1 | M28: =SUM(J28:L28) -> 6 | P28: Febrero | Q28: =SUM(C$3:C28) -> 58 | R28: =SUM(D$3:D28) -> 29 | S28: =SUM(E$3:E28) -> 24 | T28: =SUM(Q28:S28) -> 111
B29: Marzo | C29: =COUNTIFS('Datos Preescolar'!$E:$E,C$2,'Datos Preescolar'!$C:$C,">=01/03/2025",'Datos Preescolar'!$C:$C,"<=31/03/2025") -> 3 | D29: =COUNTIFS('Datos Preescolar'!$E:$E,D$2,'Datos Preescolar'!$C:$C,">=01/03/2025",'Datos Preescolar'!$C:$C,"<=31/03/2025") -> 2 | E29: =COUNTIFS('Datos Preescolar'!$E:$E,E$2,'Datos Preescolar'!$C:$C,">=01/03/2025",'Datos Preescolar'!$C:$C,"<=31/03/2025") -> 0 | F29: =SUM(C29:E29) -> 5 | I29: Marzo | J29: =SUM(C$27:C29) -> 5 | K29: =SUM(D$27:D29) -> 5 | L29: =SUM(E$27:E29) -> 1 | M29: =SUM(J29:L29) -> 11 | P29: Marzo | Q29: =SUM(C$3:C29) -> 61 | R29: =SUM(D$3:D29) -> 31 | S29: =SUM(E$3:E29) -> 24 | T29: =SUM(Q29:S29) -> 116
B30: Abril | C30: =COUNTIFS('Datos Preescolar'!$E:$E,C$2,'Datos Preescolar'!$C:$C,">=01/04/2025",'Datos Preescolar'!$C:$C,"<=30/04/2025") -> 3 | D30: =COUNTIFS('Datos Preescolar'!$E:$E,D$2,'Datos Preescolar'!$C:$C,">=01/04/2025",'Datos Preescolar'!$C:$C,"<=30/04/2025") -> 3 | E30: =COUNTIFS('Datos Preescolar'!$E:$E,E$2,'Datos Preescolar'!$C:$C,">=01/04/2025",'Datos Preescolar'!$C:$C,"<=30/04/2025") -> 1 | F30: =SUM(C30:E30) -> 7 | I30: Abril | J30: =SUM(C$27:C30) -> 8 | K30: =SUM(D$27:D30) -> 8 | L30: =SUM(E$27:E30) -> 2 | M30: =SUM(J30:L30) -> 18 | P30: Abril | Q30: =SUM(C$3:C30) -> 64 | R30: =SUM(D$3:D30) -> 34 | S30: =SUM(E$3:E30) -> 25 | T30: =SUM(Q30:S30) -> 123
B31: Mayo | C31: =COUNTIFS('Datos Preescolar'!$E:$E,C$2,'Datos Preescolar'!$C:$C,">=01/05/2025",'Datos Preescolar'!$C:$C,"<=31/05/2025") -> 2 | D31: =COUNTIFS('Datos Preescolar'!$E:$E,D$2,'Datos Preescolar'!$C:$C,">=01/05/2025",'Datos Preescolar'!$C:$C,"<=31/05/2025") -> 0 | E31: =COUNTIFS('Datos Preescolar'!$E:$E,E$2,'Datos Preescolar'!$C:$C,">=01/05/2025",'Datos Preescolar'!$C:$C,"<=31/05/2025") -> 0 | F31: =SUM(C31:E31) -> 2 | I31: Mayo | J31: =SUM(C$27:C31) -> 10 | K31: =SUM(D$27:D31) -> 8 | L31: =SUM(E$27:E31) -> 2 | M31: =SUM(J31:L31) -> 20 | P31: Mayo | Q31: =SUM(C$3:C31) -> 66 | R31: =SUM(D$3:D31) -> 34 | S31: =SUM(E$3:E31) -> 25 | T31: =SUM(Q31:S31) -> 125
B32: Junio | C32: =COUNTIFS('Datos Preescolar'!$E:$E,C$2,'Datos Preescolar'!$C:$C,">=01/06/2025",'Datos Preescolar'!$C:$C,"<=30/06/2025") -> 1 | D32: =COUNTIFS('Datos Preescolar'!$E:$E,D$2,'Datos Preescolar'!$C:$C,">=01/06/2025",'Datos Preescolar'!$C:$C,"<=30/06/2025") -> 2 | E32: =COUNTIFS('Datos Preescolar'!$E:$E,E$2,'Datos Preescolar'!$C:$C,">=01/06/2025",'Datos Preescolar'!$C:$C,"<=30/06/2025") -> 0 | F32: =SUM(C32:E32) -> 3 | I32: Junio | J32: =SUM(C$27:C32) -> 11 | K32: =SUM(D$27:D32) -> 10 | L32: =SUM(E$27:E32) -> 2 | M32: =SUM(J32:L32) -> 23 | P32: Junio | Q32: =SUM(C$3:C32) -> 67 | R32: =SUM(D$3:D32) -> 36 | S32: =SUM(E$3:E32) -> 25 | T32: =SUM(Q32:S32) -> 128
B33: Julio | C33: =COUNTIFS('Datos Preescolar'!$E:$E,C$2,'Datos Preescolar'!$C:$C,">=01/07/2025",'Datos Preescolar'!$C:$C,"<=31/07/2025") -> 4 | D33: =COUNTIFS('Datos Preescolar'!$E:$E,D$2,'Datos Preescolar'!$C:$C,">=01/07/2025",'Datos Preescolar'!$C:$C,"<=31/07/2025") -> 1 | E33: 0 | F33: =SUM(C33:E33) -> 5 | I33: Julio | J33: =SUM(C$27:C33) -> 15 | K33: =SUM(D$27:D33) -> 11 | L33: =SUM(E$27:E33) -> 2 | M33: =SUM(J33:L33) -> 28 | P33: Julio | Q33: =SUM(C$3:C33) -> 71 | R33: =SUM(D$3:D33) -> 37 | S33: =SUM(E$3:E33) -> 25 | T33: =SUM(Q33:S33) -> 133
B34: Agosto | C34: =COUNTIFS('Datos Preescolar'!$E:$E,C$2,'Datos Preescolar'!$C:$C,">=01/08/2025",'Datos Preescolar'!$C:$C,"<=31/08/2025") -> 2 | D34: =COUNTIFS('Datos Preescolar'!$E:$E,D$2,'Datos Preescolar'!$C:$C,">=01/08/2025",'Datos Preescolar'!$C:$C,"<=31/08/2025") -> 1 | E34: =COUNTIFS('Datos Preescolar'!$E:$E,E$2,'Datos Preescolar'!$C:$C,">=01/08/2025",'Datos Preescolar'!$C:$C,"<=31/08/2025") -> 2 | F34: =SUM(C34:E34) -> 5 | I34: Agosto | J34: =SUM(C$27:C34) -> 17 | K34: =SUM(D$27:D34) -> 12 | L34: =SUM(E$27:E34) -> 4 | M34: =SUM(J34:L34) -> 33 | P34: Agosto | Q34: =SUM(C$3:C34) -> 73 | R34: =SUM(D$3:D34) -> 38 | S34: =SUM(E$3:E34) -> 27 | T34: =SUM(Q34:S34) -> 138
B35: Septiembre | C35: =COUNTIFS('Datos Preescolar'!$E:$E,C$2,'Datos Preescolar'!$C:$C,">=01/09/2025",'Datos Preescolar'!$C:$C,"<=30/09/2025") -> 8 | D35: =COUNTIFS('Datos Preescolar'!$E:$E,D$2,'Datos Preescolar'!$C:$C,">=01/09/2025",'Datos Preescolar'!$C:$C,"<=30/09/2025") -> 4 | E35: =COUNTIFS('Datos Preescolar'!$E:$E,E$2,'Datos Preescolar'!$C:$C,">=01/09/2025",'Datos Preescolar'!$C:$C,"<=30/09/2025") -> 1 | F35: =SUM(C35:E35) -> 13 | I35: Septiembre | J35: =SUM(C$27:C35) -> 25 | K35: =SUM(D$27:D35) -> 16 | L35: =SUM(E$27:E35) -> 5 | M35: =SUM(J35:L35) -> 46 | P35: Septiembre | Q35: =SUM(C$3:C35) -> 81 | R35: =SUM(D$3:D35) -> 42 | S35: =SUM(E$3:E35) -> 28 | T35: =SUM(Q35:S35) -> 151
B36: Octubre | C36: =COUNTIFS('Datos Preescolar'!$E:$E,C$2,'Datos Preescolar'!$C:$C,">=01/10/2025",'Datos Preescolar'!$C:$C,"<=31/10/2025") -> 3 | D36: =COUNTIFS('Datos Preescolar'!$E:$E,D$2,'Datos Preescolar'!$C:$C,">=01/10/2025",'Datos Preescolar'!$C:$C,"<=31/10/2025") -> 1 | E36: =COUNTIFS('Datos Preescolar'!$E:$E,E$2,'Datos Preescolar'!$C:$C,">=01/10/2025",'Datos Preescolar'!$C:$C,"<=31/10/2025") -> 0 | F36: =SUM(C36:E36) -> 4 | I36: Octubre | J36: =SUM(C$27:C36) -> 28 | K36: =SUM(D$27:D36) -> 17 | L36: =SUM(E$27:E36) -> 5 | M36: =SUM(J36:L36) -> 50 | P36: Octubre | Q36: =SUM(C$3:C36) -> 84 | R36: =SUM(D$3:D36) -> 43 | S36: =SUM(E$3:E36) -> 28 | T36: =SUM(Q36:S36) -> 155
B37: Noviembre | C37: =COUNTIFS('Datos Preescolar'!$E:$E,C$2,'Datos Preescolar'!$C:$C,">=01/11/2025",'Datos Preescolar'!$C:$C,"<=30/11/2025") -> 4 | D37: =COUNTIFS('Datos Preescolar'!$E:$E,D$2,'Datos Preescolar'!$C:$C,">=01/11/2025",'Datos Preescolar'!$C:$C,"<=30/11/2025") -> 1 | E37: =COUNTIFS('Datos Preescolar'!$E:$E,E$2,'Datos Preescolar'!$C:$C,">=01/11/2025",'Datos Preescolar'!$C:$C,"<=30/11/2025") -> 1 | F37: =SUM(C37:E37) -> 6 | I37: Noviembre | J37: =SUM(C$27:C37) -> 32 | K37: =SUM(D$27:D37) -> 18 | L37: =SUM(E$27:E37) -> 6 | M37: =SUM(J37:L37) -> 56 | P37: Noviembre | Q37: =SUM(C$3:C37) -> 88 | R37: =SUM(D$3:D37) -> 44 | S37: =SUM(E$3:E37) -> 29 | T37: =SUM(Q37:S37) -> 161
B38: Diciembre | C38: =COUNTIFS('Datos Preescolar'!$E:$E,C$2,'Datos Preescolar'!$C:$C,">=01/12/2025",'Datos Preescolar'!$C:$C,"<=31/12/2025") -> 2 | D38: =COUNTIFS('Datos Preescolar'!$E:$E,D$2,'Datos Preescolar'!$C:$C,">=01/12/2025",'Datos Preescolar'!$C:$C,"<=31/12/2025") -> 0 | E38: =COUNTIFS('Datos Preescolar'!$E:$E,E$2,'Datos Preescolar'!$C:$C,">=01/12/2025",'Datos Preescolar'!$C:$C,"<=31/12/2025") -> 2 | F38: =SUM(C38:E38) -> 4 | I38: Diciembre | J38: =SUM(C$27:C38) -> 34 | K38: =SUM(D$27:D38) -> 18 | L38: =SUM(E$27:E38) -> 8 | M38: =SUM(J38:L38) -> 60 | P38: Diciembre | Q38: =SUM(C$3:C38) -> 90 | R38: =SUM(D$3:D38) -> 44 | S38: =SUM(E$3:E38) -> 31 | T38: =SUM(Q38:S38) -> 165
B41: Inicia observación por mes | I41: Inicia observación acumulado por año | P41: Inicia observación acumulado todos los años
B42: MES | C42: Prejardín | D42: Jardín | E42: Transición | F42: TOTAL | I42: MES | J42: Prejardín | K42: Jardín | L42: Transición | M42: TOTAL | P42: MES | Q42: Prejardín | R42: Jardín | S42: Transición | T42: TOTAL
...

Sheet Primaria
B1: Citas de información por mes | K1: Citas de información acumulado por año | T1: Citas de información acumulado todos los años
B2: MES | C2: 1° | D2: 2° | E2: 3° | F2: 4° | G2: 5° | H2: TOTAL | K2: MES | L2: 1° | M2: 2° | N2: 3° | O2: 4° | P2: 5° | Q2: TOTAL | T2: MES | U2: 1° | V2: 2° | W2: 3° | X2: 4° | Y2: 5° | Z2: TOTAL
A3: 2023 | B3: Enero | C3: =COUNTIFS('Datos Primaria'!$E:$E,C$2,'Datos Primaria'!$C:$C,">=01/01/2023",'Datos Primaria'!$C:$C,"<=31/01/2023") -> 2 | D3: =COUNTIFS('Datos Primaria'!$E:$E,D$2,'Datos Primaria'!$C:$C,">=01/01/2023",'Datos Primaria'!$C:$C,"<=31/01/2023") -> 1 | E3: =COUNTIFS('Datos Primaria'!$E:$E,E$2,'Datos Primaria'!$C:$C,">=01/01/2023",'Datos Primaria'!$C:$C,"<=31/01/2023") -> 4 | F3: =COUNTIFS('Datos Primaria'!$E:$E,F$2,'Datos Primaria'!$C:$C,">=01/01/2023",'Datos Primaria'!$C:$C,"<=31/01/2023") -> 1 | G3: =COUNTIFS('Datos Primaria'!$E:$E,G$2,'Datos Primaria'!$C:$C,">=01/01/2023",'Datos Primaria'!$C:$C,"<=31/01/2023") -> 1 | H3: =SUM(C3:G3) -> 9 | J3: =A3 -> 2023 | K3: Enero | L3: =SUM(C$3:C3) -> 2 | M3: =SUM(D$3:D3) -> 1 | N3: =SUM(E$3:E3) -> 4 | O3: =SUM(F$3:F3) -> 1 | P3: =SUM(G$3:G3) -> 1 | Q3: =SUM(L3:P3) -> 9 | S3: =A3 -> 2023 | T3: Enero | U3: =SUM(C$3:C3) -> 2 | V3: =SUM(D$3:D3) -> 1 | W3: =SUM(E$3:E3) -> 4 | X3: =SUM(F$3:F3) -> 1 | Y3: =SUM(G$3:G3) -> 1 | Z3: =SUM(U3:Y3) -> 9
B4: Febrero | C4: =COUNTIFS('Datos Primaria'!$E:$E,C$2,'Datos Primaria'!$C:$C,">=01/02/2023",'Datos Primaria'!$C:$C,"<=28/02/2023") -> 1 | D4: =COUNTIFS('Datos Primaria'!$E:$E,D$2,'Datos Primaria'!$C:$C,">=01/02/2023",'Datos Primaria'!$C:$C,"<=28/02/2023") -> 0 | E4: =COUNTIFS('Datos Primaria'!$E:$E,E$2,'Datos Primaria'!$C:$C,">=01/02/2023",'Datos Primaria'!$C:$C,"<=28/02/2023") -> 0 | F4: =COUNTIFS('Datos Primaria'!$E:$E,F$2,'Datos Primaria'!$C:$C,">=01/02/2023",'Datos Primaria'!$C:$C,"<=28/02/2023") -> 1 | G4: =COUNTIFS('Datos Primaria'!$E:$E,G$2,'Datos Primaria'!$C:$C,">=01/02/2023",'Datos Primaria'!$C:$C,"<=28/02/2023") -> 3 | H4: =SUM(C4:G4) -> 5 | K4: Febrero | L4: =SUM(C$3:C4) -> 3 | M4: =SUM(D$3:D4) -> 1 | N4: =SUM(E$3:E4) -> 4 | O4: =SUM(F$3:F4) -> 2 | P4: =SUM(G$3:G4) -> 4 | Q4: =SUM(L4:P4) -> 14 | T4: Febrero | U4: =SUM(C$3:C4) -> 3 | V4: =SUM(D$3:D4) -> 1 | W4: =SUM(E$3:E4) -> 4 | X4: =SUM(F$3:F4) -> 2 | Y4: =SUM(G$3:G4) -> 4 | Z4: =SUM(U4:Y4) -> 14
B5: Marzo | C5: =COUNTIFS('Datos Primaria'!$E:$E,C$2,'Datos Primaria'!$C:$C,">=01/03/2023",'Datos Primaria'!$C:$C,"<=31/03/2023") -> 1 | D5: =COUNTIFS('Datos Primaria'!$E:$E,D$2,'Datos Primaria'!$C:$C,">=01/03/2023",'Datos Primaria'!$C:$C,"<=31/03/2023") -> 1 | E5: =COUNTIFS('Datos Primaria'!$E:$E,E$2,'Datos Primaria'!$C:$C,">=01/03/2023",'Datos Primaria'!$C:$C,"<=31/03/2023") -> 0 | F5: =COUNTIFS('Datos Primaria'!$E:$E,F$2,'Datos Primaria'!$C:$C,">=01/03/2023",'Datos Primaria'!$C:$C,"<=31/03/2023") -> 0 | G5: =COUNTIFS('Datos Primaria'!$E:$E,G$2,'Datos Primaria'!$C:$C,">=01/03/2023",'Datos Primaria'!$C:$C,"<=31/03/2023") -> 0 | H5: =SUM(C5:G5) -> 2 | K5: Marzo | L5: =SUM(C$3:C5) -> 4 | M5: =SUM(D$3:D5) -> 2 | N5: =SUM(E$3:E5) -> 4 | O5: =SUM(F$3:F5) -> 2 | P5: =SUM(G$3:G5) -> 4 | Q5: =SUM(L5:P5) -> 16 | T5: Marzo | U5: =SUM(C$3:C5) -> 4 | V5: =SUM(D$3:D5) -> 2 | W5: =SUM(E$3:E5) -> 4 | X5: =SUM(F$3:F5) -> 2 | Y5: =SUM(G$3:G5) -> 4 | Z5: =SUM(U5:Y5) -> 16
B6: Abril | C6: =COUNTIFS('Datos Primaria'!$E:$E,C$2,'Datos Primaria'!$C:$C,">=01/04/2023",'Datos Primaria'!$C:$C,"<=30/04/2023") -> 1 | D6: =COUNTIFS('Datos Primaria'!$E:$E,D$2,'Datos Primaria'!$C:$C,">=01/04/2023",'Datos Primaria'!$C:$C,"<=30/04/2023") -> 1 | E6: =COUNTIFS('Datos Primaria'!$E:$E,E$2,'Datos Primaria'!$C:$C,">=01/04/2023",'Datos Primaria'!$C:$C,"<=30/04/2023") -> 2 | F6: =COUNTIFS('Datos Primaria'!$E:$E,F$2,'Datos Primaria'!$C:$C,">=01/04/2023",'Datos Primaria'!$C:$C,"<=30/04/2023") -> 1 | G6: =COUNTIFS('Datos Primaria'!$E:$E,G$2,'Datos Primaria'!$C:$C,">=01/04/2023",'Datos Primaria'!$C:$C,"<=30/04/2023") -> 1 | H6: =SUM(C6:G6) -> 6 | K6: Abril | L6: =SUM(C$3:C6) -> 5 | M6: =SUM(D$3:D6) -> 3 | N6: =SUM(E$3:E6) -> 6 | O6: =SUM(F$3:F6) -> 3 | P6: =SUM(G$3:G6) -> 5 | Q6: =SUM(L6:P6) -> 22 | T6: Abril | U6: =SUM(C$3:C6) -> 5 | V6: =SUM(D$3:D6) -> 3 | W6: =SUM(E$3:E6) -> 6 | X6: =SUM(F$3:F6) -> 3 | Y6: =SUM(G$3:G6) -> 5 | Z6: =SUM(U6:Y6) -> 22
B7: Mayo | C7: =COUNTIFS('Datos Primaria'!$E:$E,C$2,'Datos Primaria'!$C:$C,">=01/05/2023",'Datos Primaria'!$C:$C,"<=31/05/2023") -> 0 | D7: =COUNTIFS('Datos Primaria'!$E:$E,D$2,'Datos Primaria'!$C:$C,">=01/05/2023",'Datos Primaria'!$C:$C,"<=31/05/2023") -> 2 | E7: =COUNTIFS('Datos Primaria'!$E:$E,E$2,'Datos Primaria'!$C:$C,">=01/05/2023",'Datos Primaria'!$C:$C,"<=31/05/2023") -> 1 | F7: =COUNTIFS('Datos Primaria'!$E:$E,F$2,'Datos Primaria'!$C:$C,">=01/05/2023",'Datos Primaria'!$C:$C,"<=31/05/2023") -> 0 | G7: =COUNTIFS('Datos Primaria'!$E:$E,G$2,'Datos Primaria'!$C:$C,">=01/05/2023",'Datos Primaria'!$C:$C,"<=31/05/2023") -> 1 | H7: =SUM(C7:G7) -> 4 | K7: Mayo | L7: =SUM(C$3:C7) -> 5 | M7: =SUM(D$3:D7) -> 5 | N7: =SUM(E$3:E7) -> 7 | O7: =SUM(F$3:F7) -> 3 | P7: =SUM(G$3:G7) -> 6 | Q7: =SUM(L7:P7) -> 26 | T7: Mayo | U7: =SUM(C$3:C7) -> 5 | V7: =SUM(D$3:D7) -> 5 | W7: =SUM(E$3:E7) -> 7 | X7: =SUM(F$3:F7) -> 3 | Y7: =SUM(G$3:G7) -> 6 | Z7: =SUM(U7:Y7) -> 26
B8: Junio | C8: =COUNTIFS('Datos Primaria'!$E:$E,C$2,'Datos Primaria'!$C:$C,">=01/06/2023",'Datos Primaria'!$C:$C,"<=30/06/2023") -> 3 | D8: =COUNTIFS('Datos Primaria'!$E:$E,D$2,'Datos Primaria'!$C:$C,">=01/06/2023",'Datos Primaria'!$C:$C,"<=30/06/2023") -> 2 | E8: =COUNTIFS('Datos Primaria'!$E:$E,E$2,'Datos Primaria'!$C:$C,">=01/06/2023",'Datos Primaria'!$C:$C,"<=30/06/2023") -> 2 | F8: =COUNTIFS('Datos Primaria'!$E:$E,F$2,'Datos Primaria'!$C:$C,">=01/06/2023",'Datos Primaria'!$C:$C,"<=30/06/2023") -> 1 | G8: =COUNTIFS('Datos Primaria'!$E:$E,G$2,'Datos Primaria'!$C:$C,">=01/06/2023",'Datos Primaria'!$C:$C,"<=30/06/2023") -> 3 | H8: =SUM(C8:G8) -> 11 | K8: Junio | L8: =SUM(C$3:C8) -> 8 | M8: =SUM(D$3:D8) -> 7 | N8: =SUM(E$3:E8) -> 9 | O8: =SUM(F$3:F8) -> 4 | P8: =SUM(G$3:G8) -> 9 | Q8: =SUM(L8:P8) -> 37 | T8: Junio | U8: =SUM(C$3:C8) -> 8 | V8: =SUM(D$3:D8) -> 7 | W8: =SUM(E$3:E8) -> 9 | X8: =SUM(F$3:F8) -> 4 | Y8: =SUM(G$3:G8) -> 9 | Z8: =SUM(U8:Y8) -> 37
B9: Julio | C9: =COUNTIFS('Datos Primaria'!$E:$E,C$2,'Datos Primaria'!$C:$C,">=01/07/2023",'Datos Primaria'!$C:$C,"<=31/07/2023") -> 3 | D9: =COUNTIFS('Datos Primaria'!$E:$E,D$2,'Datos Primaria'!$C:$C,">=01/07/2023",'Datos Primaria'!$C:$C,"<=31/07/2023") -> 0 | E9: =COUNTIFS('Datos Primaria'!$E:$E,E$2,'Datos Primaria'!$C:$C,">=01/07/2023",'Datos Primaria'!$C:$C,"<=31/07/2023") -> 4 | F9: =COUNTIFS('Datos Primaria'!$E:$E,F$2,'Datos Primaria'!$C:$C,">=01/07/2023",'Datos Primaria'!$C:$C,"<=31/07/2023") -> 2 | G9: =COUNTIFS('Datos Primaria'!$E:$E,G$2,'Datos Primaria'!$C:$C,">=01/07/2023",'Datos Primaria'!$C:$C,"<=31/07/2023") -> 2 | H9: =SUM(C9:G9) -> 11 | K9: Julio | L9: =SUM(C$3:C9) -> 11 | M9: =SUM(D$3:D9) -> 7 | N9: =SUM(E$3:E9) -> 13 | O9: =SUM(F$3:F9) -> 6 | P9: =SUM(G$3:G9) -> 11 | Q9: =SUM(L9:P9) -> 48 | T9: Julio | U9: =SUM(C$3:C9) -> 11 | V9: =SUM(D$3:D9) -> 7 | W9: =SUM(E$3:E9) -> 13 | X9: =SUM(F$3:F9) -> 6 | Y9: =SUM(G$3:G9) -> 11 | Z9: =SUM(U9:Y9) -> 48
B10: Agosto | C10: =COUNTIFS('Datos Primaria'!$E:$E,C$2,'Datos Primaria'!$C:$C,">=01/08/2023",'Datos Primaria'!$C:$C,"<=31/08/2023") -> 6 | D10: =COUNTIFS('Datos Primaria'!$E:$E,D$2,'Datos Primaria'!$C:$C,">=01/08/2023",'Datos Primaria'!$C:$C,"<=31/08/2023") -> 1 | E10: =COUNTIFS('Datos Primaria'!$E:$E,E$2,'Datos Primaria'!$C:$C,">=01/08/2023",'Datos Primaria'!$C:$C,"<=31/08/2023") -> 2 | F10: =COUNTIFS('Datos Primaria'!$E:$E,F$2,'Datos Primaria'!$C:$C,">=01/08/2023",'Datos Primaria'!$C:$C,"<=31/08/2023") -> 4 | G10: =COUNTIFS('Datos Primaria'!$E:$E,G$2,'Datos Primaria'!$C:$C,">=01/08/2023",'Datos Primaria'!$C:$C,"<=31/08/2023") -> 4 | H10: =SUM(C10:G10) -> 17 | K10: Agosto | L10: =SUM(C$3:C10) -> 17 | M10: =SUM(D$3:D10) -> 8 | N10: =SUM(E$3:E10) -> 15 | O10: =SUM(F$3:F10) -> 10 | P10: =SUM(G$3:G10) -> 15 | Q10: =SUM(L10:P10) -> 65 | T10: Agosto | U10: =SUM(C$3:C10) -> 17 | V10: =SUM(D$3:D10) -> 8 | W10: =SUM(E$3:E10) -> 15 | X10: =SUM(F$3:F10) -> 10 | Y10: =SUM(G$3:G10) -> 15 | Z10: =SUM(U10:Y10) -> 65
